Workbook
Name CLIENTE: [1]CADASTRO!$E$5:$E$154
Name PROJETO: [1]CADASTRO!$C$5:$C$154
Name RESPONSAVEL: [1]CADASTRO!$D$5:$D$154

Sheet GRAF % ATEND
L2: GRÁFICO DE GESTÃO DE REFUGO QUALIDADE | AJ2: REVISÃO: | AM2: 01
AJ3: PÁGINA: | AM3: 01/01
AJ4: EMISSÃO: | AM4: JAN/2024
C7: ACUMULADO - ANO - (%) | O7: TOTAL - MÊS - (%) | AH7: EVOLUÇÃO - SEM - (%)
C20: DIÁRIO: | F20: 46023 | L20: A | N20: 46053
C46: PPM ACUMULADO - ANO
C59: PPM - DIÁRIO
B84: Analise dos maiores impactos
B125: Analise dos maiores impactos - Por modo de Falha

Sheet RESULTADO
C2: Real | N2: Projeção | U2: QTD | Z2: Valor Fechamento (Controladoria)
C3: Ref SPR | D3: Ref SCI | E3: Fat | F3: % | G3: Obj | H3: Aceitavél | I3: SPR | J3: SCI | K3: Total | L3: Média/dia | N3: WD | O3: Ref | P3: Fat | Q3: SPR | R3: SCI | S3: Total | T3: % | U3: Produzido | V3: Ref. | W3: PPM | X3: Meta | Z3: SPR | AA3: SCI | AB3: Total
A4: 1 | B4: Jan | C4: =SUMIF(DADOS_GRAF!$L:$L,$A4,DADOS_GRAF!$W:$W) -> #N/A | D4: =SUMIF(DADOS_GRAF!$L:$L,$A4,DADOS_GRAF!$X:$X) -> 0 | E4: =SUMIF(DADOS_GRAF!$L:$L,$A4,DADOS_GRAF!$Y:$Y) -> 34589820 | F4: =IFERROR(C4/E4,#N/A) -> #N/A | G4: 0.0028 | H4: 0.003 | I4: =IF(Z4="",SUMIF(DADOS_GRAF!$L:$L,$A4,DADOS_GRAF!$W:$W)/$E4,Z4) -> #N/A | J4: =IF(AA4="",SUMIF(DADOS_GRAF!$L:$L,$A4,DADOS_GRAF!$X:$X)/$E4,AA4) -> 0 | K4: =I4+J4 -> #N/A | L4: =(C4+D4)/COUNTIFS(DADOS_GRAF!AC:AC,"x",DADOS_GRAF!L:L,A4) -> #N/A | M4: Jan | N4: 20 | O4: =((C4+D4)/COUNTIFS(DADOS_GRAF!AC:AC,"x",DADOS_GRAF!L:L,A4))*N4 -> #N/A | Q4: =IFERROR(VLOOKUP(A4,$A$4:$C$15,3,FALSE)/P4,0) -> 0 | R4: =VLOOKUP(A4,$A$4:$D$15,4,FALSE)/P4 -> #DIV/0! | S4: =R4+Q4 -> #DIV/0! | T4: =O4/P4 -> #N/A | U4: =SUM(DADOS_GRAF!T3:T33) -> 874567 | V4: =SUMIF(DADOS_GRAF!L3:L155,A4,DADOS_GRAF!R3:R155)+SUMIF(DADOS_GRAF!L3:L155,A4,DADOS_GRAF!S3:S155) -> 24680.6 | W4: =(V4/U4)*1000000 -> 28220.365 | X4: 4600 | Y4: Jan | AB4: =SUM(Z4:AA4) -> 0
A5: =A4+1 -> 2 | B5: Fev | C5: =SUMIF(DADOS_GRAF!$L:$L,$A5,DADOS_GRAF!$W:$W) -> 0 | D5: =SUMIF(DADOS_GRAF!$L:$L,$A5,DADOS_GRAF!$X:$X) -> 0 | E5: =SUMIF(DADOS_GRAF!$L:$L,$A5,DADOS_GRAF!$Y:$Y) -> 0 | F5: =IFERROR(C5/E5,"") | G5: 0.0028 | H5: 0.003 | M5: Fev | N5: 20 | O5: =((C5+D5)/COUNTIFS(DADOS_GRAF!AC:AC,"x",DADOS_GRAF!L:L,A5))*N5 -> #DIV/0! | Q5: =IFERROR(VLOOKUP(A5,$A$4:$C$15,3,FALSE)/P5,0) -> 0 | R5: =VLOOKUP(A5,$A$4:$D$15,4,FALSE)/P5 -> #DIV/0! | S5: =R5+Q5 -> #DIV/0! | T5: =O5/P5 -> #DIV/0! | V5: =SUMIF(DADOS_GRAF!L4:L155,A5,DADOS_GRAF!R4:R155)+SUMIF(DADOS_GRAF!L4:L155,A5,DADOS_GRAF!S4:S155) -> 24462.8 | W5: =V5/U5*10^6 -> #DIV/0! | X5: 4600 | Y5: Fev | AB5: =SUM(Z5:AA5) -> 0
A6: =A5+1 -> 3 | B6: Mar | C6: =SUMIF(DADOS_GRAF!$L:$L,$A6,DADOS_GRAF!$W:$W) -> 0 | D6: =SUMIF(DADOS_GRAF!$L:$L,$A6,DADOS_GRAF!$X:$X) -> 0 | E6: =SUMIF(DADOS_GRAF!$L:$L,$A6,DADOS_GRAF!$Y:$Y) -> 0 | F6: =IFERROR(C6/E6,"") | G6: 0.0028 | H6: 0.003 | M6: Mar | N6: 21 | O6: =((C6+D6)/COUNTIFS(DADOS_GRAF!AC:AC,"x",DADOS_GRAF!L:L,A6))*N6 -> #DIV/0! | Q6: =IFERROR(VLOOKUP(A6,$A$4:$C$15,3,FALSE)/P6,0) -> 0 | R6: =VLOOKUP(A6,$A$4:$D$15,4,FALSE)/P6 -> #DIV/0! | S6: =R6+Q6 -> #DIV/0! | T6: =O6/P6 -> #DIV/0! | V6: =SUMIF(DADOS_GRAF!L5:L155,A6,DADOS_GRAF!R5:R155)+SUMIF(DADOS_GRAF!L5:L155,A6,DADOS_GRAF!S5:S155) -> 2789 | W6: =V6/U6*10^6 -> #DIV/0! | X6: 4600 | Y6: Mar | AB6: =SUM(Z6:AA6) -> 0
A7: =A6+1 -> 4 | B7: Abr | C7: =SUMIF(DADOS_GRAF!$L:$L,$A7,DADOS_GRAF!$W:$W) -> 0 | D7: =SUMIF(DADOS_GRAF!$L:$L,$A7,DADOS_GRAF!$X:$X) -> 0 | E7: =SUMIF(DADOS_GRAF!$L:$L,$A7,DADOS_GRAF!$Y:$Y) -> 0 | F7: =IFERROR(C7/E7,"") | G7: 0.0028 | H7: 0.003 | M7: Abr | N7: 20 | O7: =((C7+D7)/COUNTIFS(DADOS_GRAF!AC:AC,"x",DADOS_GRAF!L:L,A7))*N7 -> #DIV/0! | Q7: =IFERROR(VLOOKUP(A7,$A$4:$C$15,3,FALSE)/P7,0) -> 0 | R7: =VLOOKUP(A7,$A$4:$D$15,4,FALSE)/P7 -> #DIV/0! | S7: =R7+Q7 -> #DIV/0! | T7: =O7/P7 -> #DIV/0! | V7: =SUM(DADOS_GRAF!S93:S122) -> 0 | W7: =V7/U7*10^6 -> #DIV/0! | X7: 4600 | Y7: Abr | AB7: =SUM(Z7:AA7) -> 0
A8: =A7+1 -> 5 | B8: Mai | C8: =SUMIF(DADOS_GRAF!$L:$L,$A8,DADOS_GRAF!$W:$W) -> 0 | D8: =SUMIF(DADOS_GRAF!$L:$L,$A8,DADOS_GRAF!$X:$X) -> 0 | E8: =SUMIF(DADOS_GRAF!$L:$L,$A8,DADOS_GRAF!$Y:$Y) -> 0 | F8: =IFERROR(C8/E8,"") | G8: 0.0028 | H8: 0.003 | M8: Mai | N8: 21 | O8: =((C8+D8)/COUNTIFS(DADOS_GRAF!AC:AC,"x",DADOS_GRAF!L:L,A8))*N8 -> #DIV/0! | Q8: =IFERROR(VLOOKUP(A8,$A$4:$C$15,3,FALSE)/P8,0) -> 0 | R8: =VLOOKUP(A8,$A$4:$D$15,4,FALSE)/P8 -> #DIV/0! | S8: =R8+Q8 -> #DIV/0! | T8: =O8/P8 -> #DIV/0! | V8: =SUMIF(DADOS_GRAF!L7:L155,A8,DADOS_GRAF!R7:R155)+SUMIF(DADOS_GRAF!L7:L155,A8,DADOS_GRAF!S7:S155) -> 0 | W8: =V8/U8*10^6 -> #DIV/0! | X8: 4600 | Y8: Mai | AB8: =SUM(Z8:AA8) -> 0
A9: =A8+1 -> 6 | B9: Jun | C9: =SUMIF(DADOS_GRAF!$L:$L,$A9,DADOS_GRAF!$W:$W) -> 0 | D9: =SUMIF(DADOS_GRAF!$L:$L,$A9,DADOS_GRAF!$X:$X) -> 0 | E9: =SUMIF(DADOS_GRAF!$L:$L,$A9,DADOS_GRAF!$Y:$Y) -> 0 | F9: =IFERROR(C9/E9,"") | G9: 0.0028 | H9: 0.003 | M9: Jun | N9: 20 | O9: =((C9+D9)/COUNTIFS(DADOS_GRAF!AC:AC,"x",DADOS_GRAF!L:L,A9))*N9 -> #DIV/0! | Q9: =IFERROR(VLOOKUP(A9,$A$4:$C$15,3,FALSE)/P9,0) -> 0 | R9: =VLOOKUP(A9,$A$4:$D$15,4,FALSE)/P9 -> #DIV/0! | S9: =R9+Q9 -> #DIV/0! | T9: =O9/P9 -> #DIV/0! | V9: =SUMIF(DADOS_GRAF!L8:L155,A9,DADOS_GRAF!R8:R155)+SUMIF(DADOS_GRAF!L8:L155,A9,DADOS_GRAF!S8:S155) -> 0 | W9: =V9/U9*10^6 -> #DIV/0! | X9: 4600 | Y9: Jun | AB9: =SUM(Z9:AA9) -> 0
A10: =A9+1 -> 7 | B10: Jul | C10: =SUMIF(DADOS_GRAF!$L:$L,$A10,DADOS_GRAF!$W:$W) -> 0 | D10: =SUMIF(DADOS_GRAF!$L:$L,$A10,DADOS_GRAF!$X:$X) -> 0 | E10: =SUMIF(DADOS_GRAF!$L:$L,$A10,DADOS_GRAF!$Y:$Y) -> 0 | F10: =IFERROR(C10/E10,"") | G10: 0.0028 | H10: 0.003 | M10: Jul | N10: 22 | O10: =((C10+D10)/COUNTIFS(DADOS_GRAF!AC:AC,"x",DADOS_GRAF!L:L,A10))*N10 -> #DIV/0! | Q10: =IFERROR(VLOOKUP(A10,$A$4:$C$15,3,FALSE)/P10,0) -> 0 | R10: =VLOOKUP(A10,$A$4:$D$15,4,FALSE)/P10 -> #DIV/0! | S10: =R10+Q10 -> #DIV/0! | T10: =O10/P10 -> #DIV/0! | V10: =SUMIF(DADOS_GRAF!L9:L155,A10,DADOS_GRAF!R9:R155)+SUMIF(DADOS_GRAF!L9:L155,A10,DADOS_GRAF!S9:S155) -> 0 | W10: =V10/U10*10^6 -> #DIV/0! | X10: 4600 | Y10: Jul | AB10: =SUM(Z10:AA10) -> 0
A11: =A10+1 -> 8 | B11: Ago | C11: =SUMIF(DADOS_GRAF!$L:$L,$A11,DADOS_GRAF!$W:$W) -> 0 | D11: =SUMIF(DADOS_GRAF!$L:$L,$A11,DADOS_GRAF!$X:$X) -> 0 | E11: =SUMIF(DADOS_GRAF!$L:$L,$A11,DADOS_GRAF!$Y:$Y) -> 0 | G11: 0.0028 | H11: 0.003 | M11: Ago | N11: 21 | O11: =((C11+D11)/COUNTIFS(DADOS_GRAF!AC:AC,"x",DADOS_GRAF!L:L,A11))*N11 -> #DIV/0! | Q11: =IFERROR(VLOOKUP(A11,$A$4:$C$15,3,FALSE)/P11,0) -> 0 | R11: =VLOOKUP(A11,$A$4:$D$15,4,FALSE)/P11 -> #DIV/0! | S11: =R11+Q11 -> #DIV/0! | T11: =O11/P11 -> #DIV/0! | V11: =SUMIF(DADOS_GRAF!L10:L156,A11,DADOS_GRAF!R10:R156)+SUMIF(DADOS_GRAF!L10:L156,A11,DADOS_GRAF!S10:S156) -> 0 | W11: =V11/U11*10^6 -> #DIV/0! | X11: 4600 | Y11: Ago | AB11: =SUM(Z11:AA11) -> 0
A12: =A11+1 -> 9 | B12: Set | C12: =SUMIF(DADOS_GRAF!$L:$L,$A12,DADOS_GRAF!$W:$W) -> 0 | D12: =SUMIF(DADOS_GRAF!$L:$L,$A12,DADOS_GRAF!$X:$X) -> 0 | E12: =SUMIF(DADOS_GRAF!$L:$L,$A12,DADOS_GRAF!$Y:$Y) -> 0 | F12: =IFERROR(C12/E12,"") | G12: 0.0028 | H12: 0.003 | M12: Set | N12: 21 | O12: =((C12+D12)/COUNTIFS(DADOS_GRAF!AC:AC,"x",DADOS_GRAF!L:L,A12))*N12 -> #DIV/0! | Q12: =IFERROR(VLOOKUP(A12,$A$4:$C$15,3,FALSE)/P12,0) -> 0 | R12: =VLOOKUP(A12,$A$4:$D$15,4,FALSE)/P12 -> #DIV/0! | S12: =R12+Q12 -> #DIV/0! | T12: =O12/P12 -> #DIV/0! | V12: =SUMIF(DADOS_GRAF!L11:L155,A12,DADOS_GRAF!R11:R155)+SUMIF(DADOS_GRAF!L11:L155,A12,DADOS_GRAF!S11:S155) -> 0 | W12: =V12/U12*10^6 -> #DIV/0! | X12: 4600 | Y12: Set | AB12: =SUM(Z12:AA12) -> 0
A13: =A12+1 -> 10 | B13: Out | C13: =SUMIF(DADOS_GRAF!$L:$L,$A13,DADOS_GRAF!$W:$W) -> 0 | D13: =SUMIF(DADOS_GRAF!$L:$L,$A13,DADOS_GRAF!$X:$X) -> 0 | E13: =SUMIF(DADOS_GRAF!$L:$L,$A13,DADOS_GRAF!$Y:$Y) -> 0 | F13: =IFERROR(C13/E13,"") | G13: 0.0028 | H13: 0.003 | M13: Out | N13: 23 | O13: =((C13+D13)/COUNTIFS(DADOS_GRAF!AC:AC,"x",DADOS_GRAF!L:L,A13))*N13 -> #DIV/0! | Q13: =IFERROR(VLOOKUP(A13,$A$4:$C$15,3,FALSE)/P13,0) -> 0 | R13: =VLOOKUP(A13,$A$4:$D$15,4,FALSE)/P13 -> #DIV/0! | S13: =R13+Q13 -> #DIV/0! | T13: =O13/P13 -> #DIV/0! | V13: =SUMIF(DADOS_GRAF!L12:L155,A13,DADOS_GRAF!R12:R155)+SUMIF(DADOS_GRAF!L12:L155,A13,DADOS_GRAF!S12:S155) -> 0 | W13: =V13/U13*10^6 -> #DIV/0! | X13: 4600 | Y13: Out | AB13: =SUM(Z13:AA13) -> 0
A14: =A13+1 -> 11 | B14: Nov | C14: =SUMIF(DADOS_GRAF!$L:$L,$A14,DADOS_GRAF!$W:$W) -> 0 | D14: =SUMIF(DADOS_GRAF!$L:$L,$A14,DADOS_GRAF!$X:$X) -> 0 | E14: =SUMIF(DADOS_GRAF!$L:$L,$A14,DADOS_GRAF!$Y:$Y) -> 0 | F14: =IFERROR(C14/E14,"") | G14: 0.0028 | H14: 0.003 | M14: Nov | N14: 19 | O14: =((C14+D14)/COUNTIFS(DADOS_GRAF!AC:AC,"x",DADOS_GRAF!L:L,A14))*N14 -> #DIV/0! | Q14: =IFERROR(VLOOKUP(A14,$A$4:$C$15,3,FALSE)/P14,0) -> 0 | R14: =VLOOKUP(A14,$A$4:$D$15,4,FALSE)/P14 -> #DIV/0! | S14: =R14+Q14 -> #DIV/0! | T14: =O14/P14 -> #DIV/0! | V14: =SUMIF(DADOS_GRAF!L13:L155,A14,DADOS_GRAF!R13:R155)+SUMIF(DADOS_GRAF!L13:L155,A14,DADOS_GRAF!S13:S155) -> 0 | W14: =V14/U14*10^6 -> #DIV/0! | X14: 4600 | Y14: Nov | AB14: =SUM(Z14:AA14) -> 0
A15: =A14+1 -> 12 | B15: Dez | C15: =SUMIF(DADOS_GRAF!$L:$L,$A15,DADOS_GRAF!$W:$W) -> 0 | D15: =SUMIF(DADOS_GRAF!$L:$L,$A15,DADOS_GRAF!$X:$X) -> 0 | E15: =SUMIF(DADOS_GRAF!$L:$L,$A15,DADOS_GRAF!$Y:$Y) -> 0 | F15: =IFERROR(C15/E15,"") | G15: 0.0028 | H15: 0.003 | M15: Dez | N15: 20 | O15: =((C15+D15)/COUNTIFS(DADOS_GRAF!AC:AC,"x",DADOS_GRAF!L:L,A15))*N15 -> #DIV/0! | Q15: =IFERROR(VLOOKUP(A15,$A$4:$C$15,3,FALSE)/P15,0) -> 0 | R15: =VLOOKUP(A15,$A$4:$D$15,4,FALSE)/P15 -> #DIV/0! | S15: =R15+Q15 -> #DIV/0! | T15: =O15/P15 -> #DIV/0! | V15: =SUMIF(DADOS_GRAF!L14:L155,A15,DADOS_GRAF!R14:R155)+SUMIF(DADOS_GRAF!L14:L155,A15,DADOS_GRAF!S14:S155) -> 0 | W15: =V15/U15*10^6 -> #DIV/0! | X15: 4600 | Y15: Dez | AB15: =SUM(Z15:AA15) -> 0
N16: =SUM(N4:N15) -> 248 | U16: =SUM(U4:U15) -> 874567 | V16: =SUM(V4:V15) -> 51932.4 | W16: =V16/(U16+V16)*10^6 -> 56052.276 | X16: 4600
C19: Ano | J19: Semana | P19: PPM _ Ano | V19: Semana
C20: % | D20: 2023 | E20: 2024 | F20: 2025 | I20: =TODAY() -> 46088 | J20: =K20-1 -> 7 | K20: =L20-1 -> 8 | L20: =M20-1 -> 9 | M20: =WEEKNUM(I20) -> 10 | P20: N. | Q20: 2023 | R20: 2024 | S20: 2025 | U20: =TODAY() -> 46088 | V20: =W20-1 -> 7 | W20: =X20-1 -> 8 | X20: =Y20-1 -> 9 | Y20: =WEEKNUM(U20) -> 10
C21: SPR | D21: 1067811 | E21: 686772.24 | F21: =SUMIF(DADOS_GRAF!M:M,F20,DADOS_GRAF!W:W) -> 0 | I21: SPR | J21: =SUMIF(DADOS_GRAF!$N:$N,J$20,DADOS_GRAF!$W:$W) -> 0 | K21: =SUMIF(DADOS_GRAF!$N:$N,K$20,DADOS_GRAF!$W:$W) -> 0 | L21: =SUMIF(DADOS_GRAF!$N:$N,L$20,DADOS_GRAF!$W:$W) -> 0 | M21: =SUMIF(DADOS_GRAF!$N:$N,M$20,DADOS_GRAF!$W:$W) -> 0 | P21: Produzido | R21: 19895189 | S21: =U16 -> 874567 | U21: Produção | V21: =SUMIF(DADOS_GRAF!$N:$N,V$20,DADOS_GRAF!$T:$T) -> 0 | W21: =SUMIF(DADOS_GRAF!$N:$N,W$20,DADOS_GRAF!$T:$T) -> 0 | X21: =SUMIF(DADOS_GRAF!$N:$N,X$20,DADOS_GRAF!$T:$T) -> 0 | Y21: =SUMIF(DADOS_GRAF!$N:$N,Y$20,DADOS_GRAF!$T:$T) -> 0
C22: SCI | D22: 89555.854 | E22: 103639.3 | F22: =SUMIF(DADOS_GRAF!M:M,F20,DADOS_GRAF!X:X) -> 0 | I22: SCI | J22: =SUMIF(DADOS_GRAF!$N:$N,J$20,DADOS_GRAF!$X:$X) -> 0 | K22: =SUMIF(DADOS_GRAF!$N:$N,K$20,DADOS_GRAF!$X:$X) -> 0 | L22: =SUMIF(DADOS_GRAF!$N:$N,L$20,DADOS_GRAF!$X:$X) -> 0 | M22: =SUMIF(DADOS_GRAF!$N:$N,M$20,DADOS_GRAF!$X:$X) -> 0 | P22: Refugado | R22: 104611.99 | S22: =V16 -> 51932.4 | U22: Refugo | V22: =SUMIF(DADOS_GRAF!$N:$N,V$20,DADOS_GRAF!$S:$S) -> 4324 | W22: =SUMIF(DADOS_GRAF!$N:$N,W$20,DADOS_GRAF!$S:$S) -> 4176.5 | X22: =SUMIF(DADOS_GRAF!$N:$N,X$20,DADOS_GRAF!$S:$S) -> 3486.4 | Y22: =SUMIF(DADOS_GRAF!$N:$N,Y$20,DADOS_GRAF!$S:$S) -> 2434.5
C23: Fat | D23: 2.4357079e+08 | E23: 2.3582263e+08 | F23: =SUMIF(DADOS_GRAF!M:M,F20,DADOS_GRAF!Y:Y) -> 0 | I23: Fat (R$) | J23: =SUMIF(DADOS_GRAF!$N:$N,J$20,DADOS_GRAF!$Y:$Y) -> 0 | K23: =SUMIF(DADOS_GRAF!$N:$N,K$20,DADOS_GRAF!$Y:$Y) -> 0 | L23: =SUMIF(DADOS_GRAF!$N:$N,L$20,DADOS_GRAF!$Y:$Y) -> 0 | M23: =SUMIF(DADOS_GRAF!$N:$N,M$20,DADOS_GRAF!$Y:$Y) -> 0 | P23: PPM | Q23: =SUM(Q25:Q25) -> 0 | R23: =R22/R21*1000000 -> 5258.1552 | S23: =S22/S21*10^6 -> 59380.699 | U23: PPM | V23: =V22/V21*1000000 -> #DIV/0! | W23: =W22/W21*1000000 -> #DIV/0! | X23: =X22/X21*1000000 -> #DIV/0! | Y23: =Y22/Y21*1000000 -> #DIV/0!
C24: SPR | D24: =D21/D23 -> 0.0043839863 | E24: =E21/E23 -> 0.0029122406 | F24: =F21/F23 -> #DIV/0! | I24: Total | J24: =IFERROR(J21/J23,#N/A) -> #N/A | K24: =IFERROR(K21/K23,#N/A) -> #N/A | L24: =IFERROR(L21/L23,#N/A) -> #N/A | M24: =IFERROR(M21/M23,#N/A) -> #N/A | P24: Obj | R24: 4600 | U24: Obj | V24: 4600 | W24: 4600 | X24: 4600 | Y24: 4600
C25: SCI | D25: =D22/D23 -> 0.00036767896 | E25: =E22/E23 -> 0.00043947986 | F25: =F22/F23 -> #DIV/0! | I25: SPR | J25: =J21/J23 -> #DIV/0! | K25: =K21/K23 -> #DIV/0! | L25: =L21/L23 -> #DIV/0! | M25: =M21/M23 -> #DIV/0!
C26: Total | D26: =SUM(D24:D25) -> 0.0047516653 | E26: =SUM(E24:E25) -> 0.0033517205 | F26: =SUM(F24:F25) -> #DIV/0! | I26: SCI | J26: =J22/J23 -> #DIV/0! | K26: =K22/K23 -> #DIV/0! | L26: =L22/L23 -> #DIV/0! | M26: =M22/M23 -> #DIV/0!
C27: Obj | D27: 0.0048 | E27: 0.0035 | F27: 0.0025 | I27: Total | J27: =SUM(J25:J26) -> #DIV/0! | K27: =SUM(K25:K26) -> #DIV/0! | L27: =SUM(L25:L26) -> #DIV/0! | M27: =SUM(M25:M26) -> #DIV/0!
I28: Obj | J28: 0.0025 | K28: 0.0025 | L28: 0.0025 | M28: 0.0025

Sheet DADOS_GRAF
L1: Dados de Ref.
C2: Dia | D2: Ref | E2: Fat | F2: % | G2: Obj | H2: SPR | I2: SCI | J2: Total | L2: Mês | M2: Ano | N2: Sem | O2: Data | P2: Dia | Q2: SPR (Qtde) | R2: SCI (Qtde) | S2: Refugo (Tol) | T2: Prod. Dia | U2: Meta (PPM) | V2: PPM (Dia) | W2: SPR (R$) | X2: SCI (R$) | Y2: Fat | Z2: Total | AA2: SPR | AB2: SCI | AC2: Dias | AE2: Fat. ACM | AH2: Ano | AN2: Semana | AU2: Real
B3: =TEXT(WEEKDAY(C3),"ddd") -> qui | C3: =O3 -> 46023 | D3: =IFERROR(SUMIF(O:O,C3,W:W),#N/A) -> 0 | E3: =IFERROR(SUMIF(O:O,C3,Y:Y),#N/A) -> 0 | F3: =IFERROR(D3/E3,#N/A) -> #N/A | G3: 0.0035 | H3: =IF(E3=0,#N/A,IFERROR(SUMIF(O:O,C3,W:W),#N/A)/E3) -> #N/A | I3: =IF(E3=0,#N/A,IFERROR(SUMIF(O:O,C3,X:X),#N/A)/E3) -> #N/A | J3: =SUM(H3:I3) -> #N/A | L3: =MONTH(O3) -> 1 | M3: =YEAR(O3) -> 2026 | N3: =WEEKNUM(O3) -> 1 | O3: 46023 | P3: =TEXT(WEEKDAY(O3),"ddd") -> qui | Q3: =SUMIF('SPR - QTD'!$A:$A,DADOS_GRAF!O3,'SPR - QTD'!$H:$H) -> 0 | R3: =SUMIF('SCI - QTD'!$A:$A,DADOS_GRAF!O3,'SCI - QTD'!$H:$H) -> 0 | S3: =SUM(Q3:R3) -> 0 | U3: 4600 | V3: =(S3/T3)*10^6 -> #DIV/0! | W3: =SUMIF('SPR - QTD'!$A:$A,DADOS_GRAF!O3,'SPR - QTD'!$M:$M) -> 0 | X3: =SUMIF('SCI - QTD'!$A:$A,DADOS_GRAF!O3,'SCI - QTD'!$L:$L) -> 0 | AH3: % | AI3: 2021 | AJ3: 2022 | AK3: 2023 | AN3: 22 | AO3: =AN3+1 -> 23 | AP3: =AO3+1 -> 24 | AQ3: =AP3+1 -> 25 | AU3: Ref | AV3: Fat | AW3: % | AX3: Obj | AY3: SPR | AZ3: SCI | BA3: Total | BB3: Média/dia
B4: =TEXT(WEEKDAY(C4),"ddd") -> sex | C4: =O4 -> 46024 | D4: =IFERROR(SUMIF(O:O,C4,W:W),#N/A) -> 0 | E4: =IFERROR(SUMIF(O:O,C4,Y:Y),#N/A) -> 0 | F4: =IFERROR(D4/E4,#N/A) -> #N/A | G4: 0.0035 | H4: =IF(E4=0,#N/A,IFERROR(SUMIF(O:O,C4,W:W),#N/A)/E4) -> #N/A | I4: =IF(E4=0,#N/A,IFERROR(SUMIF(O:O,C4,X:X),#N/A)/E4) -> #N/A | J4: =SUM(H4:I4) -> #N/A | L4: =MONTH(O4) -> 1 | M4: =YEAR(O4) -> 2026 | N4: =WEEKNUM(O4) -> 1 | O4: 46024 | P4: =TEXT(WEEKDAY(O4),"ddd") -> sex | Q4: =SUMIF('SPR - QTD'!$A:$A,DADOS_GRAF!O4,'SPR - QTD'!$H:$H) -> 0 | R4: =SUMIF('SCI - QTD'!$A:$A,DADOS_GRAF!O4,'SCI - QTD'!$H:$H) -> 0 | S4: =SUM(Q4:R4) -> 0 | U4: 4600 | V4: =(S4/T4)*10^6 -> #DIV/0! | W4: =SUMIF('SPR - QTD'!$A:$A,DADOS_GRAF!O4,'SPR - QTD'!$M:$M) -> 0 | X4: =SUMIF('SCI - QTD'!$A:$A,DADOS_GRAF!O4,'SCI - QTD'!$L:$L) -> 0 | AH4: SPR | AK4: =SUMIF(M:M,AK3,W:W) -> 0 | AM4: SPR | AN4: =SUMIF($N:$N,AN$3,W:W) -> 0 | AO4: =SUMIF($N:$N,AO$3,W:W) -> 0 | AP4: =SUMIF($N:$N,AP$3,W:W) -> 0 | AQ4: =SUMIF($N:$N,AQ$3,W:W) -> 0 | AS4: 1 | AT4: Jan | AU4: =SUMIF($L:$L,$AS4,$W:$W) -> #N/A | AW4: =IFERROR(AU4/AV4,#N/A) -> #N/A | AX4: 0.0048 | AY4: =IF(AV20="",SUMIF(L:L,$AS4,W:W)/$AV4,AV20) -> 0.0082 | AZ4: =IF(AW20="",SUMIF(L:L,$AS4,X:X)/$AV4,AW20) -> 0.0002 | BA4: =AY4+AZ4 -> 0.0084
B5: =TEXT(WEEKDAY(C5),"ddd") -> sáb | C5: =O5 -> 46025 | D5: =IFERROR(SUMIF(O:O,C5,W:W),#N/A) -> 1388.1498 | E5: =IFERROR(SUMIF(O:O,C5,Y:Y),#N/A) -> 0 | F5: =IFERROR(D5/E5,#N/A) -> #N/A | G5: 0.0035 | H5: =IF(E5=0,#N/A,IFERROR(SUMIF(O:O,C5,W:W),#N/A)/E5) -> #N/A | I5: =IF(E5=0,#N/A,IFERROR(SUMIF(O:O,C5,X:X),#N/A)/E5) -> #N/A | J5: =SUM(H5:I5) -> #N/A | L5: =MONTH(O5) -> 1 | M5: =YEAR(O5) -> 2026 | N5: =WEEKNUM(O5) -> 1 | O5: 46025 | P5: =TEXT(WEEKDAY(O5),"ddd") -> sáb | Q5: =SUMIF('SPR - QTD'!$A:$A,DADOS_GRAF!O5,'SPR - QTD'!$H:$H) -> 64 | R5: =SUMIF('SCI - QTD'!$A:$A,DADOS_GRAF!O5,'SCI - QTD'!$H:$H) -> 0 | S5: =SUM(Q5:R5) -> 64 | U5: 4600 | V5: =(S5/T5)*10^6 -> #DIV/0! | W5: =SUMIF('SPR - QTD'!$A:$A,DADOS_GRAF!O5,'SPR - QTD'!$M:$M) -> 1388.1498 | X5: =SUMIF('SCI - QTD'!$A:$A,DADOS_GRAF!O5,'SCI - QTD'!$L:$L) -> 0 | AH5: SCI | AK5: =SUMIF(M:M,AK3,X:X) -> 0 | AM5: SCI | AN5: =SUMIF($N:$N,AN$3,X:X) -> 0 | AO5: =SUMIF($N:$N,AO$3,$X:$X) -> 0 | AP5: =SUMIF($N:$N,AP$3,$X:$X) -> 0 | AQ5: =SUMIF($N:$N,AQ$3,$X:$X) -> 0 | AS5: =AS4+1 -> 2 | AT5: Fev | AU5: =SUMIF($L:$L,$AS5,$W:$W) -> 0 | AW5: =IFERROR(AU5/AV5,#N/A) -> #N/A | AX5: 0.0048 | AY5: =IF(AV21="",SUMIF(L:L,$AS5,W:W)/$AV5,AV21) -> 0.0085 | AZ5: =IF(AW21="",SUMIF(L:L,$AS5,X:X)/$AV5,AW21) -> 0.0008 | BA5: =AY5+AZ5 -> 0.0093
B6: =TEXT(WEEKDAY(C6),"ddd") -> dom | C6: =O6 -> 46026 | D6: =IFERROR(SUMIF(O:O,C6,W:W),#N/A) -> 0 | E6: =IFERROR(SUMIF(O:O,C6,Y:Y),#N/A) -> 0 | F6: =IFERROR(D6/E6,#N/A) -> #N/A | G6: 0.0035 | H6: =IF(E6=0,#N/A,IFERROR(SUMIF(O:O,C6,W:W),#N/A)/E6) -> #N/A | I6: =IF(E6=0,#N/A,IFERROR(SUMIF(O:O,C6,X:X),#N/A)/E6) -> #N/A | J6: =SUM(H6:I6) -> #N/A | L6: =MONTH(O6) -> 1 | M6: =YEAR(O6) -> 2026 | N6: =WEEKNUM(O6) -> 2 | O6: 46026 | P6: =TEXT(WEEKDAY(O6),"ddd") -> dom | Q6: =SUMIF('SPR - QTD'!$A:$A,DADOS_GRAF!O6,'SPR - QTD'!$H:$H) -> 0 | R6: =SUMIF('SCI - QTD'!$A:$A,DADOS_GRAF!O6,'SCI - QTD'!$H:$H) -> 0 | S6: =SUM(Q6:R6) -> 0 | U6: 4600 | V6: =(S6/T6)*10^6 -> #DIV/0! | W6: =SUMIF('SPR - QTD'!$A:$A,DADOS_GRAF!O6,'SPR - QTD'!$M:$M) -> 0 | X6: =SUMIF('SCI - QTD'!$A:$A,DADOS_GRAF!O6,'SCI - QTD'!$L:$L) -> 0 | AH6: Fat | AK6: =SUMIF(M:M,AK3,Y:Y)+19384943.75+17112096.0589364+21975693.13 -> 58472733 | AM6: Fat (R$) | AN6: =SUMIF($N:$N,AN$3,Y:Y) -> 0 | AO6: =SUMIF($N:$N,AO$3,Y:Y) -> 0 | AP6: =SUMIF($N:$N,AP$3,Y:Y) -> 0 | AQ6: =SUMIF($N:$N,AQ$3,Y:Y) -> 0 | AS6: =AS5+1 -> 3 | AT6: Mar | AU6: =SUMIF($L:$L,$AS6,$W:$W) -> 0 | AW6: 0.0082 | AX6: 0.0048 | AY6: =IF(AV22="",SUMIF(L:L,$AS6,W:W)/$AV6,AV22) -> 0.0069 | AZ6: =IF(AW22="",SUMIF(L:L,$AS6,X:X)/$AV6,AW22) -> 0.0005 | BA6: =AY6+AZ6 -> 0.0074
B7: =TEXT(WEEKDAY(C7),"ddd") -> seg | C7: =O7 -> 46027 | D7: =IFERROR(SUMIF(O:O,C7,W:W),#N/A) -> 2401.7793 | E7: =IFERROR(SUMIF(O:O,C7,Y:Y),#N/A) -> 480505.16 | F7: =IFERROR(D7/E7,#N/A) -> 0.0049984464 | G7: 0.0035 | H7: =IF(E7=0,#N/A,IFERROR(SUMIF(O:O,C7,W:W),#N/A)/E7) -> 0.0049984464 | I7: =IF(E7=0,#N/A,IFERROR(SUMIF(O:O,C7,X:X),#N/A)/E7) -> 0 | J7: =SUM(H7:I7) -> 0.0049984464 | L7: =MONTH(O7) -> 1 | M7: =YEAR(O7) -> 2026 | N7: =WEEKNUM(O7) -> 2 | O7: 46027 | P7: =TEXT(WEEKDAY(O7),"ddd") -> seg | Q7: =SUMIF('SPR - QTD'!$A:$A,DADOS_GRAF!O7,'SPR - QTD'!$H:$H) -> 329 | R7: =SUMIF('SCI - QTD'!$A:$A,DADOS_GRAF!O7,'SCI - QTD'!$H:$H) -> 248.5 | S7: =SUM(Q7:R7) -> 577.5 | T7: 25253 | U7: 4600 | V7: =(S7/T7)*10^6 -> 22868.57 | W7: =SUMIF('SPR - QTD'!$A:$A,DADOS_GRAF!O7,'SPR - QTD'!$M:$M) -> 2401.7793 | X7: =SUMIF('SCI - QTD'!$A:$A,DADOS_GRAF!O7,'SCI - QTD'!$L:$L) -> 0 | Y7: =AE7-AE4 -> 480505.16 | Z7: =IFERROR((W7+X7)/Y7,#N/A) -> 0.0049984464 | AA7: =IF(Y7="",#N/A,W7/Y7) -> 0.0049984464 | AB7: =IF(Y7="",#N/A,X7/Y7) -> 0 | AC7: X | AE7: 480505.16 | AH7: SPR | AI7: 0.0051 | AJ7: 0.0051 | AK7: =AK4/AK6 -> 0 | AM7: Total | AN7: =IFERROR(AN4/AN6,#N/A) -> #N/A | AO7: =IFERROR(AO4/AO6,#N/A) -> #N/A | AP7: =IFERROR(AP4/AP6,#N/A) -> #N/A | AQ7: =IFERROR(AQ4/AQ6,#N/A) -> #N/A | AS7: =AS6+1 -> 4 | AT7: Abr | AU7: =ABS(SUMIF($L:$L,$AS7,$W:$W))+ABS(SUMIF($L:$L,$AS7,$X:$X)) -> 0 | AW7: =IFERROR(AU7/AV7,#N/A) -> #N/A | AX7: 0.0048 | AY7: =IF(AV23="",SUMIF(L:L,$AS7,W:W)/$AV7,AV23) -> 0.0037442268 | AZ7: =IF(AW23="",SUMIF(L:L,$AS7,X:X)/$AV7,AW23) -> 0.00023653866 | BA7: =AY7+AZ7 -> 0.0039807654
B8: =TEXT(WEEKDAY(C8),"ddd") -> ter | C8: =O8 -> 46028 | D8: =IFERROR(SUMIF(O:O,C8,W:W),#N/A) -> 3268.8147 | E8: =IFERROR(SUMIF(O:O,C8,Y:Y),#N/A) -> 467023.42 | F8: =IFERROR(D8/E8,#N/A) -> 0.0069992523 | G8: 0.0035 | H8: =IF(E8=0,#N/A,IFERROR(SUMIF(O:O,C8,W:W),#N/A)/E8) -> 0.0069992523 | I8: =IF(E8=0,#N/A,IFERROR(SUMIF(O:O,C8,X:X),#N/A)/E8) -> 0 | J8: =SUM(H8:I8) -> 0.0069992523 | L8: =MONTH(O8) -> 1 | M8: =YEAR(O8) -> 2026 | N8: =WEEKNUM(O8) -> 2 | O8: 46028 | P8: =TEXT(WEEKDAY(O8),"ddd") -> ter | Q8: =SUMIF('SPR - QTD'!$A:$A,DADOS_GRAF!O8,'SPR - QTD'!$H:$H) -> 308 | R8: =SUMIF('SCI - QTD'!$A:$A,DADOS_GRAF!O8,'SCI - QTD'!$H:$H) -> 243 | S8: =SUM(Q8:R8) -> 551 | T8: 63514 | U8: 4600 | V8: =(S8/T8)*10^6 -> 8675.2527 | W8: =SUMIF('SPR - QTD'!$A:$A,DADOS_GRAF!O8,'SPR - QTD'!$M:$M) -> 3268.8147 | X8: =SUMIF('SCI - QTD'!$A:$A,DADOS_GRAF!O8,'SCI - QTD'!$L:$L) -> 0 | Y8: =AE8-AE7 -> 467023.42 | Z8: =IFERROR((W8+X8)/Y8,#N/A) -> 0.0069992523 | AA8: =IF(Y8="",#N/A,W8/Y8) -> 0.0069992523 | AB8: =IF(Y8="",#N/A,X8/Y8) -> 0 | AC8: X | AE8: 947528.58 | AH8: SCI | AI8: 0.0023 | AJ8: 0.0014 | AK8: =AK5/AK6 -> 0 | AM8: SPR | AN8: =AN4/AN6 -> #DIV/0! | AO8: =AO4/AO6 -> #DIV/0! | AP8: =AP4/AP6 -> #DIV/0! | AQ8: =AQ4/AQ6 -> #DIV/0! | AS8: =AS7+1 -> 5 | AT8: Mai | AU8: =SUMIF($L:$L,$AS8,$W:$W) -> 0 | AW8: =IFERROR(AU8/AV8,#N/A) -> #N/A | AX8: 0.0048 | AY8: =IF(AV24="",SUMIF(L:L,$AS8,W:W)/$AV8,AV24) -> 0.0029463182 | AZ8: =IF(AW24="",SUMIF(L:L,$AS8,X:X)/$AV8,AW24) -> 0.00024788385 | BA8: =AY8+AZ8 -> 0.0031942021
B9: =TEXT(WEEKDAY(C9),"ddd") -> qua | C9: =O9 -> 46029 | D9: =IFERROR(SUMIF(O:O,C9,W:W),#N/A) -> 2147.0155 | E9: =IFERROR(SUMIF(O:O,C9,Y:Y),#N/A) -> 529521.11 | F9: =IFERROR(D9/E9,#N/A) -> 0.0040546362 | G9: 0.0035 | H9: =IF(E9=0,#N/A,IFERROR(SUMIF(O:O,C9,W:W),#N/A)/E9) -> 0.0040546362 | I9: =IF(E9=0,#N/A,IFERROR(SUMIF(O:O,C9,X:X),#N/A)/E9) -> 0 | J9: =SUM(H9:I9) -> 0.0040546362 | L9: =MONTH(O9) -> 1 | M9: =YEAR(O9) -> 2026 | N9: =WEEKNUM(O9) -> 2 | O9: 46029 | P9: =TEXT(WEEKDAY(O9),"ddd") -> qua | Q9: =SUMIF('SPR - QTD'!$A:$A,DADOS_GRAF!O9,'SPR - QTD'!$H:$H) -> 389 | R9: =SUMIF('SCI - QTD'!$A:$A,DADOS_GRAF!O9,'SCI - QTD'!$H:$H) -> 201.5 | S9: =SUM(Q9:R9) -> 590.5 | T9: 276112 | U9: 4600 | V9: =(S9/T9)*10^6 -> 2138.6249 | W9: =SUMIF('SPR - QTD'!$A:$A,DADOS_GRAF!O9,'SPR - QTD'!$M:$M) -> 2147.0155 | X9: =SUMIF('SCI - QTD'!$A:$A,DADOS_GRAF!O9,'SCI - QTD'!$L:$L) -> 0 | Y9: =AE9-AE8 -> 529521.11 | Z9: =IFERROR((W9+X9)/Y9,#N/A) -> 0.0040546362 | AA9: =IF(Y9="",#N/A,W9/Y9) -> 0.0040546362 | AB9: =IF(Y9="",#N/A,X9/Y9) -> 0 | AC9: X | AE9: 1477049.7 | AH9: Total | AI9: =SUM(AI7:AI8) -> 0.0074 | AJ9: =SUM(AJ7:AJ8) -> 0.0065 | AK9: =SUM(AK7:AK8) -> 0 | AM9: SCI | AN9: =AN5/AN6 -> #DIV/0! | AO9: =AO5/AO6 -> #DIV/0! | AP9: =AP5/AP6 -> #DIV/0! | AQ9: =AQ5/AQ6 -> #DIV/0! | AS9: =AS8+1 -> 6 | AT9: Jun | AU9: =SUMIF($L:$L,$AS9,$W:$W) -> 0 | AW9: =IFERROR(AU9/AV9,#N/A) -> #N/A | AX9: 0.0048 | AY9: =IF(AV25="",SUMIF(L:L,$AS9,W:W)/$AV9,AV25) -> #DIV/0! | AZ9: =IF(AW25="",SUMIF(L:L,$AS9,X:X)/$AV9,AW25) -> #DIV/0! | BA9: =AY9+AZ9 -> #DIV/0!
B10: =TEXT(WEEKDAY(C10),"ddd") -> qui | C10: =O10 -> 46030 | D10: =IFERROR(SUMIF(O:O,C10,W:W),#N/A) -> 2154.4435 | E10: =IFERROR(SUMIF(O:O,C10,Y:Y),#N/A) -> 665487.78 | F10: =IFERROR(D10/E10,#N/A) -> 0.0032373901 | G10: 0.0035 | H10: =IF(E10=0,#N/A,IFERROR(SUMIF(O:O,C10,W:W),#N/A)/E10) -> 0.0032373901 | I10: =IF(E10=0,#N/A,IFERROR(SUMIF(O:O,C10,X:X),#N/A)/E10) -> 0 | J10: =SUM(H10:I10) -> 0.0032373901 | L10: =MONTH(O10) -> 1 | M10: =YEAR(O10) -> 2026 | N10: =WEEKNUM(O10) -> 2 | O10: 46030 | P10: =TEXT(WEEKDAY(O10),"ddd") -> qui | Q10: =SUMIF('SPR - QTD'!$A:$A,DADOS_GRAF!O10,'SPR - QTD'!$H:$H) -> 268 | R10: =SUMIF('SCI - QTD'!$A:$A,DADOS_GRAF!O10,'SCI - QTD'!$H:$H) -> 205 | S10: =SUM(Q10:R10) -> 473 | T10: 197504 | U10: 4600 | V10: =(S10/T10)*10^6 -> 2394.8882 | W10: =SUMIF('SPR - QTD'!$A:$A,DADOS_GRAF!O10,'SPR - QTD'!$M:$M) -> 2154.4435 | X10: =SUMIF('SCI - QTD'!$A:$A,DADOS_GRAF!O10,'SCI - QTD'!$L:$L) -> 0 | Y10: =AE10-AE9 -> 665487.78 | Z10: =IFERROR((W10+X10)/Y10,#N/A) -> 0.0032373901 | AA10: =IF(Y10="",#N/A,W10/Y10) -> 0.0032373901 | AB10: =IF(Y10="",#N/A,X10/Y10) -> 0 | AC10: X | AE10: 2142537.5 | AH10: Obj | AI10: 0.0048 | AJ10: 0.0048 | AK10: 0.0048 | AM10: Total | AN10: =SUM(AN8:AN9) -> #DIV/0! | AO10: =SUM(AO8:AO9) -> #DIV/0! | AP10: =SUM(AP8:AP9) -> #DIV/0! | AQ10: =SUM(AQ8:AQ9) -> #DIV/0! | AS10: =AS9+1 -> 7 | AT10: Jul | AU10: =SUMIF($L:$L,$AS10,$W:$W) -> 0 | AW10: =IFERROR(AU10/AV10,#N/A) -> #N/A | AX10: 0.0048
B11: =TEXT(WEEKDAY(C11),"ddd") -> sex | C11: =O11 -> 46031 | D11: =IFERROR(SUMIF(O:O,C11,W:W),#N/A) -> 4601.8529 | E11: =IFERROR(SUMIF(O:O,C11,Y:Y),#N/A) -> 827610.04 | F11: =IFERROR(D11/E11,#N/A) -> 0.0055604121 | G11: 0.0035 | H11: =IF(E11=0,#N/A,IFERROR(SUMIF(O:O,C11,W:W),#N/A)/E11) -> 0.0055604121 | I11: =IF(E11=0,#N/A,IFERROR(SUMIF(O:O,C11,X:X),#N/A)/E11) -> 0 | J11: =SUM(H11:I11) -> 0.0055604121 | L11: =MONTH(O11) -> 1 | M11: =YEAR(O11) -> 2026 | N11: =WEEKNUM(O11) -> 2 | O11: 46031 | P11: =TEXT(WEEKDAY(O11),"ddd") -> sex | Q11: =SUMIF('SPR - QTD'!$A:$A,DADOS_GRAF!O11,'SPR - QTD'!$H:$H) -> 506 | R11: =SUMIF('SCI - QTD'!$A:$A,DADOS_GRAF!O11,'SCI - QTD'!$H:$H) -> 105 | S11: =SUM(Q11:R11) -> 611 | T11: 167915 | U11: 4600 | V11: =(S11/T11)*10^6 -> 3638.7458 | W11: =SUMIF('SPR - QTD'!$A:$A,DADOS_GRAF!O11,'SPR - QTD'!$M:$M) -> 4601.8529 | X11: =SUMIF('SCI - QTD'!$A:$A,DADOS_GRAF!O11,'SCI - QTD'!$L:$L) -> 0 | Y11: =AE11-AE10 -> 827610.04 | Z11: =IFERROR((W11+X11)/Y11,#N/A) -> 0.0055604121 | AA11: =IF(Y11="",#N/A,W11/Y11) -> 0.0055604121 | AB11: =IF(Y11="",#N/A,X11/Y11) -> 0 | AC11: X | AE11: 2970147.5 | AM11: Obj | AN11: 0.0048 | AO11: 0.0048 | AP11: 0.0048 | AQ11: 0.0048 | AS11: =AS10+1 -> 8 | AT11: Ago | AU11: =SUMIF($L:$L,$AS11,$W:$W) -> 0 | AW11: =IFERROR(AU11/AV11,#N/A) -> #N/A | AX11: 0.0048
B12: =TEXT(WEEKDAY(C12),"ddd") -> sáb | C12: =O12 -> 46032 | D12: =IFERROR(SUMIF(O:O,C12,W:W),#N/A) -> 14.964262 | E12: =IFERROR(SUMIF(O:O,C12,Y:Y),#N/A) -> 0 | F12: =IFERROR(D12/E12,#N/A) -> #N/A | G12: 0.0035 | H12: =IF(E12=0,#N/A,IFERROR(SUMIF(O:O,C12,W:W),#N/A)/E12) -> #N/A | I12: =IF(E12=0,#N/A,IFERROR(SUMIF(O:O,C12,X:X),#N/A)/E12) -> #N/A | J12: =SUM(H12:I12) -> #N/A | L12: =MONTH(O12) -> 1 | M12: =YEAR(O12) -> 2026 | N12: =WEEKNUM(O12) -> 2 | O12: 46032 | P12: =TEXT(WEEKDAY(O12),"ddd") -> sáb | Q12: =SUMIF('SPR - QTD'!$A:$A,DADOS_GRAF!O12,'SPR - QTD'!$H:$H) -> 2 | R12: =SUMIF('SCI - QTD'!$A:$A,DADOS_GRAF!O12,'SCI - QTD'!$H:$H) -> 0 | S12: =SUM(Q12:R12) -> 2 | U12: 4600 | V12: =(S12/T12)*10^6 -> #DIV/0! | W12: =SUMIF('SPR - QTD'!$A:$A,DADOS_GRAF!O12,'SPR - QTD'!$M:$M) -> 14.964262 | X12: =SUMIF('SCI - QTD'!$A:$A,DADOS_GRAF!O12,'SCI - QTD'!$L:$L) -> 0 | AS12: =AS11+1 -> 9 | AT12: Set | AU12: =SUMIF($L:$L,$AS12,$W:$W) -> 0 | AW12: =IFERROR(AU12/AV12,#N/A) -> #N/A | AX12: 0.0048
B13: =TEXT(WEEKDAY(C13),"ddd") -> dom | C13: =O13 -> 46033 | D13: =IFERROR(SUMIF(O:O,C13,W:W),#N/A) -> 0 | E13: =IFERROR(SUMIF(O:O,C13,Y:Y),#N/A) -> 0 | F13: =IFERROR(D13/E13,#N/A) -> #N/A | G13: 0.0035 | H13: =IF(E13=0,#N/A,IFERROR(SUMIF(O:O,C13,W:W),#N/A)/E13) -> #N/A | I13: =IF(E13=0,#N/A,IFERROR(SUMIF(O:O,C13,X:X),#N/A)/E13) -> #N/A | J13: =SUM(H13:I13) -> #N/A | L13: =MONTH(O13) -> 1 | M13: =YEAR(O13) -> 2026 | N13: =WEEKNUM(O13) -> 3 | O13: 46033 | P13: =TEXT(WEEKDAY(O13),"ddd") -> dom | Q13: =SUMIF('SPR - QTD'!$A:$A,DADOS_GRAF!O13,'SPR - QTD'!$H:$H) -> 0 | R13: =SUMIF('SCI - QTD'!$A:$A,DADOS_GRAF!O13,'SCI - QTD'!$H:$H) -> 0 | S13: =SUM(Q13:R13) -> 0 | U13: 4600 | V13: =(S13/T13)*10^6 -> #DIV/0! | W13: =SUMIF('SPR - QTD'!$A:$A,DADOS_GRAF!O13,'SPR - QTD'!$M:$M) -> 0 | X13: =SUMIF('SCI - QTD'!$A:$A,DADOS_GRAF!O13,'SCI - QTD'!$L:$L) -> 0 | AS13: =AS12+1 -> 10 | AT13: Out | AU13: =SUMIF($L:$L,$AS13,$W:$W) -> 0 | AW13: =IFERROR(AU13/AV13,#N/A) -> #N/A | AX13: 0.0048
B14: =TEXT(WEEKDAY(C14),"ddd") -> seg | C14: =O14 -> 46034 | D14: =IFERROR(SUMIF(O:O,C14,W:W),#N/A) -> 26000 | E14: =IFERROR(SUMIF(O:O,C14,Y:Y),#N/A) -> 597891.73 | F14: =IFERROR(D14/E14,#N/A) -> 0.043486134 | G14: 0.0035 | H14: =IF(E14=0,#N/A,IFERROR(SUMIF(O:O,C14,W:W),#N/A)/E14) -> 0.043486134 | I14: =IF(E14=0,#N/A,IFERROR(SUMIF(O:O,C14,X:X),#N/A)/E14) -> 0 | J14: =SUM(H14:I14) -> 0.043486134 | L14: =MONTH(O14) -> 1 | M14: =YEAR(O14) -> 2026 | N14: =WEEKNUM(O14) -> 3 | O14: 46034 | P14: =TEXT(WEEKDAY(O14),"ddd") -> seg | Q14: =SUMIF('SPR - QTD'!$A:$A,DADOS_GRAF!O14,'SPR - QTD'!$H:$H) -> 107 | R14: =SUMIF('SCI - QTD'!$A:$A,DADOS_GRAF!O14,'SCI - QTD'!$H:$H) -> 125 | S14: =SUM(Q14:R14) -> 232 | T14: 144269 | U14: 4600 | V14: =(S14/T14)*10^6 -> 1608.1071 | W14: 26000 | X14: =SUMIF('SCI - QTD'!$A:$A,DADOS_GRAF!O14,'SCI - QTD'!$L:$L) -> 0 | Y14: =AE14-AE11 -> 597891.73 | Z14: =IFERROR((W14+X14)/Y14,#N/A) -> 0.043486134 | AA14: =IF(Y14="",#N/A,W14/Y14) -> 0.043486134 | AB14: =IF(Y14="",#N/A,X14/Y14) -> 0 | AC14: X | AE14: 3568039.2 | AG14: 18803636 | AS14: =AS13+1 -> 11 | AT14: Nov | AU14: =SUMIF($L:$L,$AS14,$W:$W) -> 0 | AW14: =IFERROR(AU14/AV14,#N/A) -> #N/A | AX14: 0.0048
B15: =TEXT(WEEKDAY(C15),"ddd") -> ter | C15: =O15 -> 46035 | D15: =IFERROR(SUMIF(O:O,C15,W:W),#N/A) -> 12000 | E15: =IFERROR(SUMIF(O:O,C15,Y:Y),#N/A) -> 1088922.2 | F15: =IFERROR(D15/E15,#N/A) -> 0.011020071 | G15: 0.0035 | H15: =IF(E15=0,#N/A,IFERROR(SUMIF(O:O,C15,W:W),#N/A)/E15) -> 0.011020071 | I15: =IF(E15=0,#N/A,IFERROR(SUMIF(O:O,C15,X:X),#N/A)/E15) -> 0 | J15: =SUM(H15:I15) -> 0.011020071 | L15: =MONTH(O15) -> 1 | M15: =YEAR(O15) -> 2026 | N15: =WEEKNUM(O15) -> 3 | O15: 46035 | P15: =TEXT(WEEKDAY(O15),"ddd") -> ter | Q15: =SUMIF('SPR - QTD'!$A:$A,DADOS_GRAF!O15,'SPR - QTD'!$H:$H) -> 343 | R15: =SUMIF('SCI - QTD'!$A:$A,DADOS_GRAF!O15,'SCI - QTD'!$H:$H) -> 392.3 | S15: =SUM(Q15:R15) -> 735.3 | U15: 4600 | V15: =(S15/T15)*10^6 -> #DIV/0! | W15: 12000 | X15: =SUMIF('SCI - QTD'!$A:$A,DADOS_GRAF!O15,'SCI - QTD'!$L:$L) -> 0 | Y15: =AE15-AE14 -> 1088922.2 | Z15: =IFERROR((W15+X15)/Y15,#N/A) -> 0.011020071 | AA15: =IF(Y15="",#N/A,W15/Y15) -> 0.011020071 | AB15: =IF(Y15="",#N/A,X15/Y15) -> 0 | AC15: X | AE15: 4656961.5 | AS15: =AS14+1 -> 12 | AT15: Dez | AU15: =SUMIF($L:$L,$AS15,$W:$W) -> 0 | AW15: =IFERROR(AU15/AV15,#N/A) -> #N/A | AX15: 0.0048
B16: =TEXT(WEEKDAY(C16),"ddd") -> qua | C16: =O16 -> 46036 | D16: =IFERROR(SUMIF(O:O,C16,W:W),#N/A) -> 23577.688 | E16: =IFERROR(SUMIF(O:O,C16,Y:Y),#N/A) -> 1088922.2 | F16: =IFERROR(D16/E16,#N/A) -> 0.021652316 | G16: 0.0035 | H16: =IF(E16=0,#N/A,IFERROR(SUMIF(O:O,C16,W:W),#N/A)/E16) -> 0.021652316 | I16: =IF(E16=0,#N/A,IFERROR(SUMIF(O:O,C16,X:X),#N/A)/E16) -> 0 | J16: =SUM(H16:I16) -> 0.021652316 | L16: =MONTH(O16) -> 1 | M16: =YEAR(O16) -> 2026 | N16: =WEEKNUM(O16) -> 3 | O16: 46036 | P16: =TEXT(WEEKDAY(O16),"ddd") -> qua | Q16: =SUMIF('SPR - QTD'!$A:$A,DADOS_GRAF!O16,'SPR - QTD'!$H:$H) -> 2781 | R16: =SUMIF('SCI - QTD'!$A:$A,DADOS_GRAF!O16,'SCI - QTD'!$H:$H) -> 318.5 | S16: =SUM(Q16:R16) -> 3099.5 | U16: 4600 | V16: =(S16/T16)*10^6 -> #DIV/0! | W16: =SUMIF('SPR - QTD'!$A:$A,DADOS_GRAF!O16,'SPR - QTD'!$M:$M) -> 23577.688 | X16: =SUMIF('SCI - QTD'!$A:$A,DADOS_GRAF!O16,'SCI - QTD'!$L:$L) -> 0 | Y16: =AE16-AE15 -> 1088922.2 | Z16: =IFERROR((W16+X16)/Y16,#N/A) -> 0.021652316 | AA16: =IF(Y16="",#N/A,W16/Y16) -> 0.021652316 | AB16: =IF(Y16="",#N/A,X16/Y16) -> 0 | AC16: X | AE16: 5745883.7
B17: =TEXT(WEEKDAY(C17),"ddd") -> qui | C17: =O17 -> 46037 | D17: =IFERROR(SUMIF(O:O,C17,W:W),#N/A) -> 2443.3886 | E17: =IFERROR(SUMIF(O:O,C17,Y:Y),#N/A) -> 1242418 | F17: =IFERROR(D17/E17,#N/A) -> 0.0019666397 | G17: 0.0035 | H17: =IF(E17=0,#N/A,IFERROR(SUMIF(O:O,C17,W:W),#N/A)/E17) -> 0.0019666397 | I17: =IF(E17=0,#N/A,IFERROR(SUMIF(O:O,C17,X:X),#N/A)/E17) -> 0 | J17: =SUM(H17:I17) -> 0.0019666397 | L17: =MONTH(O17) -> 1 | M17: =YEAR(O17) -> 2026 | N17: =WEEKNUM(O17) -> 3 | O17: 46037 | P17: =TEXT(WEEKDAY(O17),"ddd") -> qui | Q17: =SUMIF('SPR - QTD'!$A:$A,DADOS_GRAF!O17,'SPR - QTD'!$H:$H) -> 467 | R17: =SUMIF('SCI - QTD'!$A:$A,DADOS_GRAF!O17,'SCI - QTD'!$H:$H) -> 209.5 | S17: =SUM(Q17:R17) -> 676.5 | U17: 4600 | V17: =(S17/T17)*10^6 -> #DIV/0! | W17: =SUMIF('SPR - QTD'!$A:$A,DADOS_GRAF!O17,'SPR - QTD'!$M:$M) -> 2443.3886 | X17: =SUMIF('SCI - QTD'!$A:$A,DADOS_GRAF!O17,'SCI - QTD'!$L:$L) -> 0 | Y17: =AE17-AE16 -> 1242418 | Z17: =IFERROR((W17+X17)/Y17,#N/A) -> 0.0019666397 | AA17: =IF(Y17="",#N/A,W17/Y17) -> 0.0019666397 | AB17: =IF(Y17="",#N/A,X17/Y17) -> 0 | AC17: X | AE17: =AE16+$AG$30 -> 6988301.7 | AV17: Valor Fechamento (Controladoria)
B18: =TEXT(WEEKDAY(C18),"ddd") -> sex | C18: =O18 -> 46038 | D18: =IFERROR(SUMIF(O:O,C18,W:W),#N/A) -> 2244.1407 | E18: =IFERROR(SUMIF(O:O,C18,Y:Y),#N/A) -> 1242418 | F18: =IFERROR(D18/E18,#N/A) -> 0.0018062686 | G18: 0.0035 | H18: =IF(E18=0,#N/A,IFERROR(SUMIF(O:O,C18,W:W),#N/A)/E18) -> 0.0018062686 | I18: =IF(E18=0,#N/A,IFERROR(SUMIF(O:O,C18,X:X),#N/A)/E18) -> 0 | J18: =SUM(H18:I18) -> 0.0018062686 | L18: =MONTH(O18) -> 1 | M18: =YEAR(O18) -> 2026 | N18: =WEEKNUM(O18) -> 3 | O18: 46038 | P18: =TEXT(WEEKDAY(O18),"ddd") -> sex | Q18: =SUMIF('SPR - QTD'!$A:$A,DADOS_GRAF!O18,'SPR - QTD'!$H:$H) -> 513 | R18: =SUMIF('SCI - QTD'!$A:$A,DADOS_GRAF!O18,'SCI - QTD'!$H:$H) -> 264.2 | S18: =SUM(Q18:R18) -> 777.2 | U18: 4600 | V18: =(S18/T18)*10^6 -> #DIV/0! | W18: =SUMIF('SPR - QTD'!$A:$A,DADOS_GRAF!O18,'SPR - QTD'!$M:$M) -> 2244.1407 | X18: =SUMIF('SCI - QTD'!$A:$A,DADOS_GRAF!O18,'SCI - QTD'!$L:$L) -> 0 | Y18: =AE18-AE17 -> 1242418 | Z18: =IFERROR((W18+X18)/Y18,#N/A) -> 0.0018062686 | AA18: =IF(Y18="",#N/A,W18/Y18) -> 0.0018062686 | AB18: =IF(Y18="",#N/A,X18/Y18) -> 0 | AC18: X | AE18: =AE17+$AG$30 -> 8230719.8 | AK18: Projeção | AQ18: QTD | BA18: Ano
B19: =TEXT(WEEKDAY(C19),"ddd") -> sáb | C19: =O19 -> 46039 | D19: =IFERROR(SUMIF(O:O,C19,W:W),#N/A) -> 0 | E19: =IFERROR(SUMIF(O:O,C19,Y:Y),#N/A) -> 0 | F19: =IFERROR(D19/E19,#N/A) -> #N/A | G19: 0.0035 | H19: =IF(E19=0,#N/A,IFERROR(SUMIF(O:O,C19,W:W),#N/A)/E19) -> #N/A | I19: =IF(E19=0,#N/A,IFERROR(SUMIF(O:O,C19,X:X),#N/A)/E19) -> #N/A | J19: =SUM(H19:I19) -> #N/A | L19: =MONTH(O19) -> 1 | M19: =YEAR(O19) -> 2026 | N19: =WEEKNUM(O19) -> 3 | O19: 46039 | P19: =TEXT(WEEKDAY(O19),"ddd") -> sáb | Q19: =SUMIF('SPR - QTD'!$A:$A,DADOS_GRAF!O19,'SPR - QTD'!$H:$H) -> 0 | R19: =SUMIF('SCI - QTD'!$A:$A,DADOS_GRAF!O19,'SCI - QTD'!$H:$H) -> 3.7 | S19: =SUM(Q19:R19) -> 3.7 | U19: 4600 | V19: =(S19/T19)*10^6 -> #DIV/0! | W19: =SUMIF('SPR - QTD'!$A:$A,DADOS_GRAF!O19,'SPR - QTD'!$M:$M) -> 0 | X19: =SUMIF('SCI - QTD'!$A:$A,DADOS_GRAF!O19,'SCI - QTD'!$L:$L) -> 0 | AJ19: WD | AK19: Ref | AL19: Fat | AM19: SPR | AN19: SCI | AO19: Total | AP19: % | AQ19: Produzido | AR19: Ref. | AS19: PPM | AV19: SPR | AW19: SCI | AX19: Total | BA19: 2021 | BB19: 2022 | BC19: 2023
B20: =TEXT(WEEKDAY(C20),"ddd") -> dom | C20: =O20 -> 46040 | D20: =IFERROR(SUMIF(O:O,C20,W:W),#N/A) -> 130.80264 | E20: =IFERROR(SUMIF(O:O,C20,Y:Y),#N/A) -> 0 | F20: =IFERROR(D20/E20,#N/A) -> #N/A | G20: 0.0035 | H20: =IF(E20=0,#N/A,IFERROR(SUMIF(O:O,C20,W:W),#N/A)/E20) -> #N/A | I20: =IF(E20=0,#N/A,IFERROR(SUMIF(O:O,C20,X:X),#N/A)/E20) -> #N/A | J20: =SUM(H20:I20) -> #N/A | L20: =MONTH(O20) -> 1 | M20: =YEAR(O20) -> 2026 | N20: =WEEKNUM(O20) -> 4 | O20: 46040 | P20: =TEXT(WEEKDAY(O20),"ddd") -> dom | Q20: =SUMIF('SPR - QTD'!$A:$A,DADOS_GRAF!O20,'SPR - QTD'!$H:$H) -> 4 | R20: =SUMIF('SCI - QTD'!$A:$A,DADOS_GRAF!O20,'SCI - QTD'!$H:$H) -> 0 | S20: =SUM(Q20:R20) -> 4 | U20: 4600 | V20: =(S20/T20)*10^6 -> #DIV/0! | W20: =SUMIF('SPR - QTD'!$A:$A,DADOS_GRAF!O20,'SPR - QTD'!$M:$M) -> 130.80264 | X20: =SUMIF('SCI - QTD'!$A:$A,DADOS_GRAF!O20,'SCI - QTD'!$L:$L) -> 0 | AH20: 1 | AI20: Jan | AJ20: 22 | AM20: =SUMIF(L:L,$AS4,W:W)/$AV4 -> #N/A | AN20: =SUMIF(L:L,$AS4,X:X)/$AV4 -> #DIV/0! | AO20: 0.0084 | AP20: =AO20 -> 0.0084 | AQ20: 1510581 | AR20: =16508+520 -> 17028 | AS20: =AR20/(AQ20+AR20)*10^6 -> 11146.831 | AT20: 1 | AU20: Jan | AV20: 0.0082 | AW20: 0.0002 | AX20: =SUM(AV20:AW20) -> 0.0084
B21: =TEXT(WEEKDAY(C21),"ddd") -> seg | C21: =O21 -> 46041 | D21: =IFERROR(SUMIF(O:O,C21,W:W),#N/A) -> 2203.0616 | E21: =IFERROR(SUMIF(O:O,C21,Y:Y),#N/A) -> 1242418 | F21: =IFERROR(D21/E21,#N/A) -> 0.0017732048 | G21: 0.0035 | H21: =IF(E21=0,#N/A,IFERROR(SUMIF(O:O,C21,W:W),#N/A)/E21) -> 0.0017732048 | I21: =IF(E21=0,#N/A,IFERROR(SUMIF(O:O,C21,X:X),#N/A)/E21) -> 0 | J21: =SUM(H21:I21) -> 0.0017732048 | L21: =MONTH(O21) -> 1 | M21: =YEAR(O21) -> 2026 | N21: =WEEKNUM(O21) -> 4 | O21: 46041 | P21: =TEXT(WEEKDAY(O21),"ddd") -> seg | Q21: =SUMIF('SPR - QTD'!$A:$A,DADOS_GRAF!O21,'SPR - QTD'!$H:$H) -> 251 | R21: =SUMIF('SCI - QTD'!$A:$A,DADOS_GRAF!O21,'SCI - QTD'!$H:$H) -> 274 | S21: =SUM(Q21:R21) -> 525 | U21: 4600 | V21: =(S21/T21)*10^6 -> #DIV/0! | W21: =SUMIF('SPR - QTD'!$A:$A,DADOS_GRAF!O21,'SPR - QTD'!$M:$M) -> 2203.0616 | X21: =SUMIF('SCI - QTD'!$A:$A,DADOS_GRAF!O21,'SCI - QTD'!$L:$L) -> 0 | Y21: =AE21-AE18 -> 1242418 | Z21: =IFERROR((W21+X21)/Y21,#N/A) -> 0.0017732048 | AA21: =IF(Y21="",#N/A,W21/Y21) -> 0.0017732048 | AB21: =IF(Y21="",#N/A,X21/Y21) -> 0 | AC21: X | AE21: =AE18+$AG$30 -> 9473137.8 | AI21: Fev | AJ21: 20 | AM21: =SUMIF(L:L,$AS5,W:W)/$AV5 -> #DIV/0! | AN21: =SUMIF(L:L,$AS5,X:X)/$AV5 -> #DIV/0! | AO21: 0.0093 | AP21: =AO21 -> 0.0093 | AQ21: 1627116 | AR21: =17433+655 -> 18088 | AS21: =AR21/(AQ21+AR21)*10^6 -> 10994.381 | AT21: =AT20+1 -> 2 | AU21: Fev | AV21: 0.0085 | AW21: 0.0008 | AX21: =SUM(AV21:AW21) -> 0.0093 | AZ21: Ref | BC21: =AK4 -> 0
B22: =TEXT(WEEKDAY(C22),"ddd") -> ter | C22: =O22 -> 46042 | D22: =IFERROR(SUMIF(O:O,C22,W:W),#N/A) -> 3561.8532 | E22: =IFERROR(SUMIF(O:O,C22,Y:Y),#N/A) -> 1242418 | F22: =IFERROR(D22/E22,#N/A) -> 0.0028668717 | G22: 0.0035 | H22: =IF(E22=0,#N/A,IFERROR(SUMIF(O:O,C22,W:W),#N/A)/E22) -> 0.0028668717 | I22: =IF(E22=0,#N/A,IFERROR(SUMIF(O:O,C22,X:X),#N/A)/E22) -> 0 | J22: =SUM(H22:I22) -> 0.0028668717 | L22: =MONTH(O22) -> 1 | M22: =YEAR(O22) -> 2026 | N22: =WEEKNUM(O22) -> 4 | O22: 46042 | P22: =TEXT(WEEKDAY(O22),"ddd") -> ter | Q22: =SUMIF('SPR - QTD'!$A:$A,DADOS_GRAF!O22,'SPR - QTD'!$H:$H) -> 390 | R22: =SUMIF('SCI - QTD'!$A:$A,DADOS_GRAF!O22,'SCI - QTD'!$H:$H) -> 386.5 | S22: =SUM(Q22:R22) -> 776.5 | U22: 4600 | V22: =(S22/T22)*10^6 -> #DIV/0! | W22: =SUMIF('SPR - QTD'!$A:$A,DADOS_GRAF!O22,'SPR - QTD'!$M:$M) -> 3561.8532 | X22: =SUMIF('SCI - QTD'!$A:$A,DADOS_GRAF!O22,'SCI - QTD'!$L:$L) -> 0 | Y22: =AE22-AE21 -> 1242418 | Z22: =IFERROR((W22+X22)/Y22,#N/A) -> 0.0028668717 | AA22: =IF(Y22="",#N/A,W22/Y22) -> 0.0028668717 | AB22: =IF(Y22="",#N/A,X22/Y22) -> 0 | AC22: X | AE22: =AE21+$AG$30 -> 10715556 | AH22: =AH21+1 -> 1 | AI22: Mar | AJ22: 23 | AM22: =SUMIF(L:L,$AS6,W:W)/$AV6 -> #DIV/0! | AN22: =SUMIF(L:L,$AS6,X:X)/$AV6 -> #DIV/0! | AO22: 0.0074 | AP22: =AO22 -> 0.0074 | AQ22: 2347220 | AR22: =19528+3708 -> 23236 | AS22: =AR22/(AQ22+AR22)*10^6 -> 9802.3334 | AT22: =AT21+1 -> 3 | AU22: Mar | AV22: 0.0069 | AW22: 0.0005 | AX22: =SUM(AV22:AW22) -> 0.0074 | AZ22: Prod | BC22: =12775539+AK4 -> 12775539
B23: =TEXT(WEEKDAY(C23),"ddd") -> qua | C23: =O23 -> 46043 | D23: =IFERROR(SUMIF(O:O,C23,W:W),#N/A) -> #N/A | E23: =IFERROR(SUMIF(O:O,C23,Y:Y),#N/A) -> 1242418 | F23: =IFERROR(D23/E23,#N/A) -> #N/A | G23: 0.0035 | H23: =IF(E23=0,#N/A,IFERROR(SUMIF(O:O,C23,W:W),#N/A)/E23) -> #N/A | I23: =IF(E23=0,#N/A,IFERROR(SUMIF(O:O,C23,X:X),#N/A)/E23) -> 0 | J23: =SUM(H23:I23) -> #N/A | L23: =MONTH(O23) -> 1 | M23: =YEAR(O23) -> 2026 | N23: =WEEKNUM(O23) -> 4 | O23: 46043 | P23: =TEXT(WEEKDAY(O23),"ddd") -> qua | Q23: =SUMIF('SPR - QTD'!$A:$A,DADOS_GRAF!O23,'SPR - QTD'!$H:$H) -> 311 | R23: =SUMIF('SCI - QTD'!$A:$A,DADOS_GRAF!O23,'SCI - QTD'!$H:$H) -> 415 | S23: =SUM(Q23:R23) -> 726 | U23: 4600 | V23: =(S23/T23)*10^6 -> #DIV/0! | W23: =SUMIF('SPR - QTD'!$A:$A,DADOS_GRAF!O23,'SPR - QTD'!$M:$M) -> #N/A | X23: =SUMIF('SCI - QTD'!$A:$A,DADOS_GRAF!O23,'SCI - QTD'!$L:$L) -> 0 | Y23: =AE23-AE22 -> 1242418 | Z23: =IFERROR((W23+X23)/Y23,#N/A) -> #N/A | AA23: =IF(Y23="",#N/A,W23/Y23) -> #N/A | AB23: =IF(Y23="",#N/A,X23/Y23) -> 0 | AC23: X | AE23: =AE22+$AG$30 -> 11957974 | AH23: =AH22+1 -> 2 | AI23: Abr | AJ23: 18 | AK23: =(AU7/COUNTIFS(AC:AC,"x",L:L,AS7)*AJ23) -> #DIV/0! | AL23: 20107770 | AM23: =SUMIF(L:L,$AS7,W:W)/$AL23 -> 0 | AN23: =SUMIF(L:L,$AS7,X:X)/$AL23 -> 0 | AO23: =AN23+AM23 -> 0 | AP23: =AO23 -> 0 | AQ23: 1787658 | AR23: =SUMIF(#REF!,DADOS_GRAF!AH23,#REF!)+SUMIF('SPR - QTD'!#REF!,DADOS_GRAF!AH23,'SPR - QTD'!#REF!) -> #REF! | AS23: =AR23/(AQ23+AR23)*10^6 -> #REF! | AT23: =AT22+1 -> 4 | AU23: Abr | AV23: 0.0037442268 | AW23: 0.00023653866 | AX23: =SUM(AV23:AW23) -> 0.0039807654
B24: =TEXT(WEEKDAY(C24),"ddd") -> qui | C24: =O24 -> 46044 | D24: =IFERROR(SUMIF(O:O,C24,W:W),#N/A) -> 2695.5664 | E24: =IFERROR(SUMIF(O:O,C24,Y:Y),#N/A) -> 1242418 | F24: =IFERROR(D24/E24,#N/A) -> 0.0021696131 | G24: 0.0035 | H24: =IF(E24=0,#N/A,IFERROR(SUMIF(O:O,C24,W:W),#N/A)/E24) -> 0.0021696131 | I24: =IF(E24=0,#N/A,IFERROR(SUMIF(O:O,C24,X:X),#N/A)/E24) -> 0 | J24: =SUM(H24:I24) -> 0.0021696131 | L24: =MONTH(O24) -> 1 | M24: =YEAR(O24) -> 2026 | N24: =WEEKNUM(O24) -> 4 | O24: 46044 | P24: =TEXT(WEEKDAY(O24),"ddd") -> qui | Q24: =SUMIF('SPR - QTD'!$A:$A,DADOS_GRAF!O24,'SPR - QTD'!$H:$H) -> 754 | R24: =SUMIF('SCI - QTD'!$A:$A,DADOS_GRAF!O24,'SCI - QTD'!$H:$H) -> 253 | S24: =SUM(Q24:R24) -> 1007 | U24: 4600 | V24: =(S24/T24)*10^6 -> #DIV/0! | W24: =SUMIF('SPR - QTD'!$A:$A,DADOS_GRAF!O24,'SPR - QTD'!$M:$M) -> 2695.5664 | X24: =SUMIF('SCI - QTD'!$A:$A,DADOS_GRAF!O24,'SCI - QTD'!$L:$L) -> 0 | Y24: =AE24-AE23 -> 1242418 | Z24: =IFERROR((W24+X24)/Y24,#N/A) -> 0.0021696131 | AA24: =IF(Y24="",#N/A,W24/Y24) -> 0.0021696131 | AB24: =IF(Y24="",#N/A,X24/Y24) -> 0 | AC24: X | AE24: =AE23+$AG$30 -> 13200392 | AH24: =AH23+1 -> 3 | AI24: Mai | AJ24: 22 | AK24: =(AU8/COUNTIFS(AC:AC,"x",L:L,AS8)*AJ24) -> #DIV/0! | AL24: 25364437 | AM24: =SUMIF(L:L,$AS8,W:W)/$AL24 -> 0 | AN24: =SUMIF(L:L,$AS8,X:X)/$AL24 -> 0 | AO24: =AN24+AM24 -> 0 | AP24: =AO24 -> 0 | AQ24: 2054062 | AR24: =SUMIF(#REF!,DADOS_GRAF!AH24,#REF!)+SUMIF('SPR - QTD'!#REF!,DADOS_GRAF!AH24,'SPR - QTD'!#REF!) -> #REF! | AS24: =AR24/(AQ24+AR24)*10^6 -> #REF! | AT24: =AT23+1 -> 5 | AU24: Mai | AV24: 0.0029463182 | AW24: 0.00024788385 | AX24: =SUM(AV24:AW24) -> 0.0031942021
B25: =TEXT(WEEKDAY(C25),"ddd") -> sex | C25: =O25 -> 46045 | D25: =IFERROR(SUMIF(O:O,C25,W:W),#N/A) -> 1827.8823 | E25: =IFERROR(SUMIF(O:O,C25,Y:Y),#N/A) -> 0 | F25: =IFERROR(D25/E25,#N/A) -> #N/A | G25: 0.0035 | H25: =IF(E25=0,#N/A,IFERROR(SUMIF(O:O,C25,W:W),#N/A)/E25) -> #N/A | I25: =IF(E25=0,#N/A,IFERROR(SUMIF(O:O,C25,X:X),#N/A)/E25) -> #N/A | J25: =SUM(H25:I25) -> #N/A | L25: =MONTH(O25) -> 1 | M25: =YEAR(O25) -> 2026 | N25: =WEEKNUM(O25) -> 4 | O25: 46045 | P25: =TEXT(WEEKDAY(O25),"ddd") -> sex | Q25: =SUMIF('SPR - QTD'!$A:$A,DADOS_GRAF!O25,'SPR - QTD'!$H:$H) -> 456 | R25: =SUMIF('SCI - QTD'!$A:$A,DADOS_GRAF!O25,'SCI - QTD'!$H:$H) -> 406.5 | S25: =SUM(Q25:R25) -> 862.5 | U25: 4600 | V25: =(S25/T25)*10^6 -> #DIV/0! | W25: =SUMIF('SPR - QTD'!$A:$A,DADOS_GRAF!O25,'SPR - QTD'!$M:$M) -> 1827.8823 | X25: =SUMIF('SCI - QTD'!$A:$A,DADOS_GRAF!O25,'SCI - QTD'!$L:$L) -> 0 | Z25: =IFERROR((W25+X25)/Y25,#N/A) -> #N/A | AA25: =IF(Y25="",#N/A,W25/Y25) -> #N/A | AB25: =IF(Y25="",#N/A,X25/Y25) -> #N/A | AC25: X | AE25: =AE24+$AG$30 -> 14442810 | AH25: =AH24+1 -> 4 | AI25: Jun | AJ25: 21 | AK25: =(AU9/COUNTIFS(AC:AC,"x",L:L,AS9)*AJ25) -> #DIV/0! | AL25: 18187627 | AM25: =SUMIF(L:L,$AS9,W:W)/$AL25 -> 0 | AN25: =SUMIF(L:L,$AS9,X:X)/$AL25 -> 0 | AO25: =AN25+AM25 -> 0 | AP25: 0.0034 | AQ25: 1668290 | AR25: =SUMIF(#REF!,DADOS_GRAF!AH25,#REF!)+SUMIF('SPR - QTD'!#REF!,DADOS_GRAF!AH25,'SPR - QTD'!#REF!) -> #REF! | AS25: =AR25/(AQ25+AR25)*10^6 -> #REF! | AT25: =AT24+1 -> 6 | AU25: Jun | BA25: 0.005 | BB25: 0.0049 | BC25: =BC21/BC22*10^6 -> 0
B26: =TEXT(WEEKDAY(C26),"ddd") -> sáb | C26: =O26 -> 46046 | D26: =IFERROR(SUMIF(O:O,C26,W:W),#N/A) -> 324.85395 | E26: =IFERROR(SUMIF(O:O,C26,Y:Y),#N/A) -> 0 | F26: =IFERROR(D26/E26,#N/A) -> #N/A | G26: 0.0035 | H26: =IF(E26=0,#N/A,IFERROR(SUMIF(O:O,C26,W:W),#N/A)/E26) -> #N/A | I26: =IF(E26=0,#N/A,IFERROR(SUMIF(O:O,C26,X:X),#N/A)/E26) -> #N/A | J26: =SUM(H26:I26) -> #N/A | L26: =MONTH(O26) -> 1 | M26: =YEAR(O26) -> 2026 | N26: =WEEKNUM(O26) -> 4 | O26: 46046 | P26: =TEXT(WEEKDAY(O26),"ddd") -> sáb | Q26: =SUMIF('SPR - QTD'!$A:$A,DADOS_GRAF!O26,'SPR - QTD'!$H:$H) -> 35 | R26: =SUMIF('SCI - QTD'!$A:$A,DADOS_GRAF!O26,'SCI - QTD'!$H:$H) -> 177 | S26: =SUM(Q26:R26) -> 212 | U26: 4600 | V26: =(S26/T26)*10^6 -> #DIV/0! | W26: =SUMIF('SPR - QTD'!$A:$A,DADOS_GRAF!O26,'SPR - QTD'!$M:$M) -> 324.85395 | X26: =SUMIF('SCI - QTD'!$A:$A,DADOS_GRAF!O26,'SCI - QTD'!$L:$L) -> 0 | AH26: =AH25+1 -> 5 | AI26: Jul | AJ26: 21 | AT26: =AT25+1 -> 7 | AU26: Jul
B27: =TEXT(WEEKDAY(C27),"ddd") -> dom | C27: =O27 -> 46047 | D27: =IFERROR(SUMIF(O:O,C27,W:W),#N/A) -> 275.58747 | E27: =IFERROR(SUMIF(O:O,C27,Y:Y),#N/A) -> 0 | F27: =IFERROR(D27/E27,#N/A) -> #N/A | G27: 0.0035 | H27: =IF(E27=0,#N/A,IFERROR(SUMIF(O:O,C27,W:W),#N/A)/E27) -> #N/A | I27: =IF(E27=0,#N/A,IFERROR(SUMIF(O:O,C27,X:X),#N/A)/E27) -> #N/A | J27: =SUM(H27:I27) -> #N/A | L27: =MONTH(O27) -> 1 | M27: =YEAR(O27) -> 2026 | N27: =WEEKNUM(O27) -> 5 | O27: 46047 | P27: =TEXT(WEEKDAY(O27),"ddd") -> dom | Q27: =SUMIF('SPR - QTD'!$A:$A,DADOS_GRAF!O27,'SPR - QTD'!$H:$H) -> 45 | R27: =SUMIF('SCI - QTD'!$A:$A,DADOS_GRAF!O27,'SCI - QTD'!$H:$H) -> 0 | S27: =SUM(Q27:R27) -> 45 | U27: 4600 | V27: =(S27/T27)*10^6 -> #DIV/0! | W27: =SUMIF('SPR - QTD'!$A:$A,DADOS_GRAF!O27,'SPR - QTD'!$M:$M) -> 275.58747 | X27: =SUMIF('SCI - QTD'!$A:$A,DADOS_GRAF!O27,'SCI - QTD'!$L:$L) -> 0 | AH27: =AH26+1 -> 6 | AI27: Ago | AJ27: 23 | AT27: =AT26+1 -> 8 | AU27: Ago
B28: =TEXT(WEEKDAY(C28),"ddd") -> seg | C28: =O28 -> 46048 | D28: =IFERROR(SUMIF(O:O,C28,W:W),#N/A) -> 1647.1582 | E28: =IFERROR(SUMIF(O:O,C28,Y:Y),#N/A) -> 1242418 | F28: =IFERROR(D28/E28,#N/A) -> 0.0013257681 | G28: 0.0035 | H28: =IF(E28=0,#N/A,IFERROR(SUMIF(O:O,C28,W:W),#N/A)/E28) -> 0.0013257681 | I28: =IF(E28=0,#N/A,IFERROR(SUMIF(O:O,C28,X:X),#N/A)/E28) -> 0 | J28: =SUM(H28:I28) -> 0.0013257681 | L28: =MONTH(O28) -> 1 | M28: =YEAR(O28) -> 2026 | N28: =WEEKNUM(O28) -> 5 | O28: 46048 | P28: =TEXT(WEEKDAY(O28),"ddd") -> seg | Q28: =SUMIF('SPR - QTD'!$A:$A,DADOS_GRAF!O28,'SPR - QTD'!$H:$H) -> 329 | R28: =SUMIF('SCI - QTD'!$A:$A,DADOS_GRAF!O28,'SCI - QTD'!$H:$H) -> 312 | S28: =SUM(Q28:R28) -> 641 | U28: 4600 | V28: =(S28/T28)*10^6 -> #DIV/0! | W28: =SUMIF('SPR - QTD'!$A:$A,DADOS_GRAF!O28,'SPR - QTD'!$M:$M) -> 1647.1582 | X28: =SUMIF('SCI - QTD'!$A:$A,DADOS_GRAF!O28,'SCI - QTD'!$L:$L) -> 0 | Y28: =AE28-AE25 -> 1242418 | Z28: =IFERROR((W28+X28)/Y28,#N/A) -> 0.0013257681 | AA28: =IF(Y28="",#N/A,W28/Y28) -> 0.0013257681 | AB28: =IF(Y28="",#N/A,X28/Y28) -> 0 | AC28: X | AE28: =AE25+$AG$30 -> 15685228 | AH28: =AH27+1 -> 7 | AI28: Set | AJ28: 20 | AT28: =AT27+1 -> 9 | AU28: Set
B29: =TEXT(WEEKDAY(C29),"ddd") -> ter | C29: =O29 -> 46049 | D29: =IFERROR(SUMIF(O:O,C29,W:W),#N/A) -> 0 | E29: =IFERROR(SUMIF(O:O,C29,Y:Y),#N/A) -> 1242418 | F29: =IFERROR(D29/E29,#N/A) -> 0 | G29: 0.0035 | H29: =IF(E29=0,#N/A,IFERROR(SUMIF(O:O,C29,W:W),#N/A)/E29) -> 0 | I29: =IF(E29=0,#N/A,IFERROR(SUMIF(O:O,C29,X:X),#N/A)/E29) -> 0 | J29: =SUM(H29:I29) -> 0 | L29: =MONTH(O29) -> 1 | M29: =YEAR(O29) -> 2026 | N29: =WEEKNUM(O29) -> 5 | O29: 46049 | P29: =TEXT(WEEKDAY(O29),"ddd") -> ter | Q29: =SUMIF('SPR - QTD'!$A:$A,DADOS_GRAF!O29,'SPR - QTD'!$H:$H) -> 606 | R29: =SUMIF('SCI - QTD'!$A:$A,DADOS_GRAF!O29,'SCI - QTD'!$H:$H) -> 429.5 | S29: =SUM(Q29:R29) -> 1035.5 | U29: 4600 | V29: =(S29/T29)*10^6 -> #DIV/0! | W29: =SUMIF('SPR - QTD'!$A:$A,DADOS_GRAF!O29,'SPR - QTD'!$M:$M) -> 0 | X29: =SUMIF('SCI - QTD'!$A:$A,DADOS_GRAF!O29,'SCI - QTD'!$L:$L) -> 0 | Y29: =AE29-AE28 -> 1242418 | Z29: =IFERROR((W29+X29)/Y29,#N/A) -> 0 | AA29: =IF(Y29="",#N/A,W29/Y29) -> 0 | AB29: =IF(Y29="",#N/A,X29/Y29) -> 0 | AC29: X | AE29: =AE28+$AG$30 -> 16927646 | AH29: =AH28+1 -> 8 | AI29: Out | AJ29: 21 | AT29: =AT28+1 -> 10 | AU29: Out
B30: =TEXT(WEEKDAY(C30),"ddd") -> qua | C30: =O30 -> 46050 | D30: =IFERROR(SUMIF(O:O,C30,W:W),#N/A) -> 0 | E30: =IFERROR(SUMIF(O:O,C30,Y:Y),#N/A) -> 0 | F30: =IFERROR(D30/E30,#N/A) -> #N/A | G30: 0.0035 | H30: =IF(E30=0,#N/A,IFERROR(SUMIF(O:O,C30,W:W),#N/A)/E30) -> #N/A | I30: =IF(E30=0,#N/A,IFERROR(SUMIF(O:O,C30,X:X),#N/A)/E30) -> #N/A | J30: =SUM(H30:I30) -> #N/A | L30: =MONTH(O30) -> 1 | M30: =YEAR(O30) -> 2026 | N30: =WEEKNUM(O30) -> 5 | O30: 46050 | P30: =TEXT(WEEKDAY(O30),"ddd") -> qua | Q30: =SUMIF('SPR - QTD'!$A:$A,DADOS_GRAF!O30,'SPR - QTD'!$H:$H) -> 527 | R30: =SUMIF('SCI - QTD'!$A:$A,DADOS_GRAF!O30,'SCI - QTD'!$H:$H) -> 835.1 | S30: =SUM(Q30:R30) -> 1362.1 | U30: 4600 | V30: =(S30/T30)*10^6 -> #DIV/0! | W30: =SUMIF('SPR - QTD'!$A:$A,DADOS_GRAF!O30,'SPR - QTD'!$M:$M) -> 0 | X30: =SUMIF('SCI - QTD'!$A:$A,DADOS_GRAF!O30,'SCI - QTD'!$L:$L) -> 0 | Z30: =IFERROR((W30+X30)/Y30,#N/A) -> #N/A | AA30: =IF(Y30="",#N/A,W30/Y30) -> #N/A | AB30: =IF(Y30="",#N/A,X30/Y30) -> #N/A | AC30: X | AG30: =(AG31-AE16)/9 -> 1242418 | AH30: =AH29+1 -> 9 | AI30: Nov | AJ30: 20 | AT30: =AT29+1 -> 11 | AU30: Nov
B31: =TEXT(WEEKDAY(C31),"ddd") -> qui | C31: =O31 -> 46051 | D31: =IFERROR(SUMIF(O:O,C31,W:W),#N/A) -> 0 | E31: =IFERROR(SUMIF(O:O,C31,Y:Y),#N/A) -> 0 | F31: =IFERROR(D31/E31,#N/A) -> #N/A | G31: 0.0035 | H31: =IF(E31=0,#N/A,IFERROR(SUMIF(O:O,C31,W:W),#N/A)/E31) -> #N/A | I31: =IF(E31=0,#N/A,IFERROR(SUMIF(O:O,C31,X:X),#N/A)/E31) -> #N/A | J31: =SUM(H31:I31) -> #N/A | L31: =MONTH(O31) -> 1 | M31: =YEAR(O31) -> 2026 | N31: =WEEKNUM(O31) -> 5 | O31: 46051 | P31: =TEXT(WEEKDAY(O31),"ddd") -> qui | Q31: =SUMIF('SPR - QTD'!$A:$A,DADOS_GRAF!O31,'SPR - QTD'!$H:$H) -> 400 | R31: =SUMIF('SCI - QTD'!$A:$A,DADOS_GRAF!O31,'SCI - QTD'!$H:$H) -> 470.5 | S31: =SUM(Q31:R31) -> 870.5 | U31: 4600 | V31: =(S31/T31)*10^6 -> #DIV/0! | W31: =SUMIF('SPR - QTD'!$A:$A,DADOS_GRAF!O31,'SPR - QTD'!$M:$M) -> 0 | X31: =SUMIF('SCI - QTD'!$A:$A,DADOS_GRAF!O31,'SCI - QTD'!$L:$L) -> 0 | Y31: =AE31-AE30 -> 0 | Z31: =IFERROR((W31+X31)/Y31,#N/A) -> #N/A | AA31: =IF(Y31="",#N/A,W31/Y31) -> #DIV/0! | AB31: =IF(Y31="",#N/A,X31/Y31) -> #DIV/0! | AC31: X | AG31: 16927646 | AH31: =AH30+1 -> 10 | AI31: Dez | AJ31: 20 | AT31: =AT30+1 -> 12 | AU31: Dez
B32: =TEXT(WEEKDAY(C32),"ddd") -> sex | C32: =O32 -> 46052 | D32: =IFERROR(SUMIF(O:O,C32,W:W),#N/A) -> 0 | E32: =IFERROR(SUMIF(O:O,C32,Y:Y),#N/A) -> 18904592 | F32: =IFERROR(D32/E32,#N/A) -> 0 | G32: 0.0035 | H32: =IF(E32=0,#N/A,IFERROR(SUMIF(O:O,C32,W:W),#N/A)/E32) -> 0 | I32: =IF(E32=0,#N/A,IFERROR(SUMIF(O:O,C32,X:X),#N/A)/E32) -> 0 | J32: =SUM(H32:I32) -> 0 | L32: =MONTH(O32) -> 1 | M32: =YEAR(O32) -> 2026 | N32: =WEEKNUM(O32) -> 5 | O32: 46052 | P32: =TEXT(WEEKDAY(O32),"ddd") -> sex | Q32: =SUMIF('SPR - QTD'!$A:$A,DADOS_GRAF!O32,'SPR - QTD'!$H:$H) -> 293 | R32: =SUMIF('SCI - QTD'!$A:$A,DADOS_GRAF!O32,'SCI - QTD'!$H:$H) -> 754 | S32: =SUM(Q32:R32) -> 1047 | U32: 4600 | V32: =(S32/T32)*10^6 -> #DIV/0! | W32: =SUMIF('SPR - QTD'!$A:$A,DADOS_GRAF!O32,'SPR - QTD'!$M:$M) -> 0 | X32: =SUMIF('SCI - QTD'!$A:$A,DADOS_GRAF!O32,'SCI - QTD'!$L:$L) -> 0 | Y32: =AE32-AE31 -> 18904592 | Z32: =IFERROR((W32+X32)/Y32,#N/A) -> 0 | AA32: =IF(Y32="",#N/A,W32/Y32) -> 0 | AB32: =IF(Y32="",#N/A,X32/Y32) -> 0 | AC32: X | AE32: 18904592 | AG32: 18803636 | AJ32: =SUM(AJ20:AJ31) -> 251
B33: =TEXT(WEEKDAY(C33),"ddd") -> sáb | C33: =O33 -> 46053 | D33: =IFERROR(SUMIF(O:O,C33,W:W),#N/A) -> 0 | E33: =IFERROR(SUMIF(O:O,C33,Y:Y),#N/A) -> 0 | F33: =IFERROR(D33/E33,#N/A) -> #N/A | G33: 0.0035 | H33: =IF(E33=0,#N/A,IFERROR(SUMIF(O:O,C33,W:W),#N/A)/E33) -> #N/A | I33: =IF(E33=0,#N/A,IFERROR(SUMIF(O:O,C33,X:X),#N/A)/E33) -> #N/A | J33: =SUM(H33:I33) -> #N/A | L33: =MONTH(O33) -> 1 | M33: =YEAR(O33) -> 2026 | N33: =WEEKNUM(O33) -> 5 | O33: 46053 | P33: =TEXT(WEEKDAY(O33),"ddd") -> sáb | Q33: =SUMIF('SPR - QTD'!$A:$A,DADOS_GRAF!O33,'SPR - QTD'!$H:$H) -> 46 | R33: =SUMIF('SCI - QTD'!$A:$A,DADOS_GRAF!O33,'SCI - QTD'!$H:$H) -> 49 | S33: =SUM(Q33:R33) -> 95 | U33: 4600 | V33: =(S33/T33)*10^6 -> #DIV/0! | W33: =SUMIF('SPR - QTD'!$A:$A,DADOS_GRAF!O33,'SPR - QTD'!$M:$M) -> 0 | X33: =SUMIF('SCI - QTD'!$A:$A,DADOS_GRAF!O33,'SCI - QTD'!$L:$L) -> 0
B34: =TEXT(WEEKDAY(C34),"ddd") -> dom | C34: =O34 -> 46054 | D34: =IFERROR(SUMIF(O:O,C34,W:W),#N/A) -> 0 | E34: =IFERROR(SUMIF(O:O,C34,Y:Y),#N/A) -> 0 | F34: =IFERROR(D34/E34,#N/A) -> #N/A | G34: 0.0035 | H34: =IF(E34=0,#N/A,IFERROR(SUMIF(O:O,C34,W:W),#N/A)/E34) -> #N/A | I34: =IF(E34=0,#N/A,IFERROR(SUMIF(O:O,C34,X:X),#N/A)/E34) -> #N/A | J34: =SUM(H34:I34) -> #N/A | L34: =MONTH(O34) -> 2 | M34: =YEAR(O34) -> 2026 | N34: =WEEKNUM(O34) -> 6 | O34: 46054 | P34: =TEXT(WEEKDAY(O34),"ddd") -> dom | Q34: =SUMIF('SPR - QTD'!$A:$A,DADOS_GRAF!O34,'SPR - QTD'!$H:$H) -> 57 | R34: =SUMIF('SCI - QTD'!$A:$A,DADOS_GRAF!O34,'SCI - QTD'!$H:$H) -> 20 | S34: =SUM(Q34:R34) -> 77 | U34: 4600 | V34: =(S34/T34)*10^6 -> #DIV/0! | W34: =SUMIF('SPR - QTD'!$A:$A,DADOS_GRAF!O34,'SPR - QTD'!$M:$M) -> 0 | X34: =SUMIF('SCI - QTD'!$A:$A,DADOS_GRAF!O34,'SCI - QTD'!$L:$L) -> 0
B35: =TEXT(WEEKDAY(C35),"ddd") -> seg | C35: =O35 -> 46055 | D35: =IFERROR(SUMIF(O:O,C35,W:W),#N/A) -> 0 | E35: =IFERROR(SUMIF(O:O,C35,Y:Y),#N/A) -> 0 | F35: =IFERROR(D35/E35,#N/A) -> #N/A | G35: 0.0035 | H35: =IF(E35=0,#N/A,IFERROR(SUMIF(O:O,C35,W:W),#N/A)/E35) -> #N/A | I35: =IF(E35=0,#N/A,IFERROR(SUMIF(O:O,C35,X:X),#N/A)/E35) -> #N/A | J35: =SUM(H35:I35) -> #N/A | L35: =MONTH(O35) -> 2 | M35: =YEAR(O35) -> 2026 | N35: =WEEKNUM(O35) -> 6 | O35: 46055 | P35: =TEXT(WEEKDAY(O35),"ddd") -> seg | Q35: =SUMIF('SPR - QTD'!$A:$A,DADOS_GRAF!O35,'SPR - QTD'!$H:$H) -> 479 | R35: =SUMIF('SCI - QTD'!$A:$A,DADOS_GRAF!O35,'SCI - QTD'!$H:$H) -> 583 | S35: =SUM(Q35:R35) -> 1062 | U35: 4600 | V35: =(S35/T35)*10^6 -> #DIV/0! | W35: =SUMIF('SPR - QTD'!$A:$A,DADOS_GRAF!O35,'SPR - QTD'!$M:$M) -> 0 | X35: =SUMIF('SCI - QTD'!$A:$A,DADOS_GRAF!O35,'SCI - QTD'!$L:$L) -> 0
B36: =TEXT(WEEKDAY(C36),"ddd") -> ter | C36: =O36 -> 46056 | D36: =IFERROR(SUMIF(O:O,C36,W:W),#N/A) -> 0 | E36: =IFERROR(SUMIF(O:O,C36,Y:Y),#N/A) -> 0 | F36: =IFERROR(D36/E36,#N/A) -> #N/A | G36: 0.0035 | H36: =IF(E36=0,#N/A,IFERROR(SUMIF(O:O,C36,W:W),#N/A)/E36) -> #N/A | I36: =IF(E36=0,#N/A,IFERROR(SUMIF(O:O,C36,X:X),#N/A)/E36) -> #N/A | J36: =SUM(H36:I36) -> #N/A | L36: =MONTH(O36) -> 2 | M36: =YEAR(O36) -> 2026 | N36: =WEEKNUM(O36) -> 6 | O36: 46056 | P36: =TEXT(WEEKDAY(O36),"ddd") -> ter | Q36: =SUMIF('SPR - QTD'!$A:$A,DADOS_GRAF!O36,'SPR - QTD'!$H:$H) -> 300 | R36: =SUMIF('SCI - QTD'!$A:$A,DADOS_GRAF!O36,'SCI - QTD'!$H:$H) -> 598 | S36: =SUM(Q36:R36) -> 898 | U36: 4600 | V36: =(S36/T36)*10^6 -> #DIV/0! | W36: =SUMIF('SPR - QTD'!$A:$A,DADOS_GRAF!O36,'SPR - QTD'!$M:$M) -> 0 | X36: =SUMIF('SCI - QTD'!$A:$A,DADOS_GRAF!O36,'SCI - QTD'!$L:$L) -> 0
B37: =TEXT(WEEKDAY(C37),"ddd") -> qua | C37: =O37 -> 46057 | D37: =IFERROR(SUMIF(O:O,C37,W:W),#N/A) -> 0 | E37: =IFERROR(SUMIF(O:O,C37,Y:Y),#N/A) -> 0 | F37: =IFERROR(D37/E37,#N/A) -> #N/A | G37: 0.0035 | H37: =IF(E37=0,#N/A,IFERROR(SUMIF(O:O,C37,W:W),#N/A)/E37) -> #N/A | I37: =IF(E37=0,#N/A,IFERROR(SUMIF(O:O,C37,X:X),#N/A)/E37) -> #N/A | J37: =SUM(H37:I37) -> #N/A | L37: =MONTH(O37) -> 2 | M37: =YEAR(O37) -> 2026 | N37: =WEEKNUM(O37) -> 6 | O37: 46057 | P37: =TEXT(WEEKDAY(O37),"ddd") -> qua | Q37: =SUMIF('SPR - QTD'!$A:$A,DADOS_GRAF!O37,'SPR - QTD'!$H:$H) -> 370 | R37: =SUMIF('SCI - QTD'!$A:$A,DADOS_GRAF!O37,'SCI - QTD'!$H:$H) -> 452.5 | S37: =SUM(Q37:R37) -> 822.5 | U37: 4600 | V37: =(S37/T37)*10^6 -> #DIV/0! | W37: =SUMIF('SPR - QTD'!$A:$A,DADOS_GRAF!O37,'SPR - QTD'!$M:$M) -> 0 | X37: =SUMIF('SCI - QTD'!$A:$A,DADOS_GRAF!O37,'SCI - QTD'!$L:$L) -> 0
B38: =TEXT(WEEKDAY(C38),"ddd") -> qui | C38: =O38 -> 46058 | D38: =IFERROR(SUMIF(O:O,C38,W:W),#N/A) -> 0 | E38: =IFERROR(SUMIF(O:O,C38,Y:Y),#N/A) -> 0 | F38: =IFERROR(D38/E38,#N/A) -> #N/A | G38: 0.0035 | H38: =IF(E38=0,#N/A,IFERROR(SUMIF(O:O,C38,W:W),#N/A)/E38) -> #N/A | I38: =IF(E38=0,#N/A,IFERROR(SUMIF(O:O,C38,X:X),#N/A)/E38) -> #N/A | J38: =SUM(H38:I38) -> #N/A | L38: =MONTH(O38) -> 2 | M38: =YEAR(O38) -> 2026 | N38: =WEEKNUM(O38) -> 6 | O38: 46058 | P38: =TEXT(WEEKDAY(O38),"ddd") -> qui | Q38: =SUMIF('SPR - QTD'!$A:$A,DADOS_GRAF!O38,'SPR - QTD'!$H:$H) -> 522 | R38: =SUMIF('SCI - QTD'!$A:$A,DADOS_GRAF!O38,'SCI - QTD'!$H:$H) -> 269.5 | S38: =SUM(Q38:R38) -> 791.5 | U38: 4600 | V38: =(S38/T38)*10^6 -> #DIV/0! | W38: =SUMIF('SPR - QTD'!$A:$A,DADOS_GRAF!O38,'SPR - QTD'!$M:$M) -> 0 | X38: =SUMIF('SCI - QTD'!$A:$A,DADOS_GRAF!O38,'SCI - QTD'!$L:$L) -> 0
B39: =TEXT(WEEKDAY(C39),"ddd") -> sex | C39: =O39 -> 46059 | D39: =IFERROR(SUMIF(O:O,C39,W:W),#N/A) -> 0 | E39: =IFERROR(SUMIF(O:O,C39,Y:Y),#N/A) -> 0 | F39: =IFERROR(D39/E39,#N/A) -> #N/A | G39: 0.0035 | H39: =IF(E39=0,#N/A,IFERROR(SUMIF(O:O,C39,W:W),#N/A)/E39) -> #N/A | I39: =IF(E39=0,#N/A,IFERROR(SUMIF(O:O,C39,X:X),#N/A)/E39) -> #N/A | J39: =SUM(H39:I39) -> #N/A | L39: =MONTH(O39) -> 2 | M39: =YEAR(O39) -> 2026 | N39: =WEEKNUM(O39) -> 6 | O39: 46059 | P39: =TEXT(WEEKDAY(O39),"ddd") -> sex | Q39: =SUMIF('SPR - QTD'!$A:$A,DADOS_GRAF!O39,'SPR - QTD'!$H:$H) -> 376 | R39: =SUMIF('SCI - QTD'!$A:$A,DADOS_GRAF!O39,'SCI - QTD'!$H:$H) -> 315.5 | S39: =SUM(Q39:R39) -> 691.5 | U39: 4600 | V39: =(S39/T39)*10^6 -> #DIV/0! | W39: =SUMIF('SPR - QTD'!$A:$A,DADOS_GRAF!O39,'SPR - QTD'!$M:$M) -> 0 | X39: =SUMIF('SCI - QTD'!$A:$A,DADOS_GRAF!O39,'SCI - QTD'!$L:$L) -> 0
B40: =TEXT(WEEKDAY(C40),"ddd") -> sáb | C40: =O40 -> 46060 | D40: =IFERROR(SUMIF(O:O,C40,W:W),#N/A) -> 0 | E40: =IFERROR(SUMIF(O:O,C40,Y:Y),#N/A) -> 0 | F40: =IFERROR(D40/E40,#N/A) -> #N/A | G40: 0.0035 | H40: =IF(E40=0,#N/A,IFERROR(SUMIF(O:O,C40,W:W),#N/A)/E40) -> #N/A | I40: =IF(E40=0,#N/A,IFERROR(SUMIF(O:O,C40,X:X),#N/A)/E40) -> #N/A | J40: =SUM(H40:I40) -> #N/A | L40: =MONTH(O40) -> 2 | M40: =YEAR(O40) -> 2026 | N40: =WEEKNUM(O40) -> 6 | O40: 46060 | P40: =TEXT(WEEKDAY(O40),"ddd") -> sáb | Q40: =SUMIF('SPR - QTD'!$A:$A,DADOS_GRAF!O40,'SPR - QTD'!$H:$H) -> 67 | R40: =SUMIF('SCI - QTD'!$A:$A,DADOS_GRAF!O40,'SCI - QTD'!$H:$H) -> 35 | S40: =SUM(Q40:R40) -> 102 | U40: 4600 | V40: =(S40/T40)*10^6 -> #DIV/0! | W40: =SUMIF('SPR - QTD'!$A:$A,DADOS_GRAF!O40,'SPR - QTD'!$M:$M) -> 0 | X40: =SUMIF('SCI - QTD'!$A:$A,DADOS_GRAF!O40,'SCI - QTD'!$L:$L) -> 0
...

Sheet SCI - QTD
A1: Data | B1: Turno | C1: PN Novo | D1: Produto | E1: Código NC | F1: Setor | G1: Máquina | H1: Qtde | I1: Responsavel | J1: Médio | K1: R$/Kg | L1: Vlr Total | M1: Qtde Suc | N1: Mês | O1: QTD
A2: 46027 | B2: 1 | C2: MDAI001325 | D2: MDAI001325 | E2: 31 | F2: 320 | G2: GUI02 | H2: 25 | I2: JOABES | J2: 0 | K2: =VLOOKUP(C2,'CUSTO CONTABIL Dez.24 A Dez.25'!$B:$J,9,0) -> 16.272928 | L2: =IF(LEFT(C2,4)="mdac",0,IF(LEFT(C2,4)="mdai",0,IF(J2=0,ABS(K2*H2),ABS(J2)))) -> 0 | M2: =IF(L2=0,0,H2) -> 0 | N2: =MONTH(A2) -> 1 | O2: =ABS(IF(H2=0,0)) -> 0
A3: 46027 | B3: 2 | C3: MDAI001325 | D3: MDAI001325 | E3: 31 | F3: 320 | G3: GUI02 | H3: 20 | I3: LESIDO | J3: 0 | K3: =VLOOKUP(C3,'CUSTO CONTABIL Dez.24 A Dez.25'!$B:$J,9,0) -> 16.272928 | L3: =IF(LEFT(C3,4)="mdac",0,IF(LEFT(C3,4)="mdai",0,IF(J3=0,ABS(K3*H3),ABS(J3)))) -> 0 | M3: =IF(L3=0,0,H3) -> 0 | N3: =MONTH(A3) -> 1 | O3: =ABS(IF(H3=0,0)) -> 0
A4: 46027 | B4: 1 | C4: MDAC001169 | D4: MDAC001169 | E4: 31 | F4: 320 | G4: PRN55 | H4: 80 | I4: FABIO | J4: 0 | K4: =VLOOKUP(C4,'CUSTO CONTABIL Dez.24 A Dez.25'!$B:$J,9,0) -> 7.0201442 | L4: =IF(LEFT(C4,4)="mdac",0,IF(LEFT(C4,4)="mdai",0,IF(J4=0,ABS(K4*H4),ABS(J4)))) -> 0 | M4: =IF(L4=0,0,H4) -> 0 | N4: =MONTH(A4) -> 1 | O4: =ABS(IF(H4=0,0)) -> 0
A5: 46027 | B5: 1 | C5: MDAI001369 | D5: MDAI001369 | E5: 31 | F5: 320 | G5: PRN40 | H5: 10 | I5: LUCAS/PAULO | J5: 0 | K5: =VLOOKUP(C5,'CUSTO CONTABIL Dez.24 A Dez.25'!$B:$J,9,0) -> 29.51846 | L5: =IF(LEFT(C5,4)="mdac",0,IF(LEFT(C5,4)="mdai",0,IF(J5=0,ABS(K5*H5),ABS(J5)))) -> 0 | M5: =IF(L5=0,0,H5) -> 0 | N5: =MONTH(A5) -> 1 | O5: =ABS(IF(H5=0,0)) -> 0
A6: 46027 | B6: 1 | C6: MDAI000978 | D6: MDAC000978 | E6: 31 | F6: 320 | G6: PRN51 | H6: 20 | I6: EDUARDO / DOUGLAS | J6: 0 | K6: =VLOOKUP(C6,'CUSTO CONTABIL Dez.24 A Dez.25'!$B:$J,9,0) -> 16.269568 | L6: =IF(LEFT(C6,4)="mdac",0,IF(LEFT(C6,4)="mdai",0,IF(J6=0,ABS(K6*H6),ABS(J6)))) -> 0 | M6: =IF(L6=0,0,H6) -> 0 | N6: =MONTH(A6) -> 1 | O6: =ABS(IF(H6=0,0)) -> 0
